Workbook

Sheet LEIA-ME
A1: PLANILHA MESTRA WINNET — precificação, margem e frete em um lugar só
A3: Resumo | B3: Fotografia executiva das margens (23/07, tarifas reais). Me peça pra regenerar após grandes edições no Simulador.
A4: Simulador | B4: O coração: 113 SKUs × 2 regiões, vivo. Edite preços/custos/tarifas e vereditos recalculam. Filtre a coluna Veredito pra ver a fila vermelha.
A5: Novo_Produto | B5: Produto novo? Digite dimensões da caixa, peso, custo e margem alvo → ela devolve a classe de frete e o PREÇO SUGERIDO. Depois teste seu preço na coluna P e veja a margem/veredito.
A6: Ref_Frete | B6: Tabela de apoio (53 regiões × custo real e cobrança das 3 classes). Alimenta as outras abas — só edite se os modelos WN mudarem na Amazon.
A7: Classificação_Frete | B7: Os 113 SKUs com peso cubado e classe validada por cotação. Consulta e histórico das reclassificações.
A8: Registro_Vendas / Livro_Vendas | B8: Registro: cada venda com margem real (linhas prontas até a 105 — NUNCA use "Inserir linha"; pedido multi-SKU = uma linha por SKU, frete só na 1ª). Livro: histórico pedido a pedido com origem Ads/Orgânico e resumo mensal.
A9: Arquivos externos: | B9: Plano_Implementacao_Amazon_Ads (operação do Ads, semanal) · Modelos_Frete (arquivo morto/backup — valores já na Amazon) · Simulador v2 (obsoleto, pode excluir).

Sheet Resumo
A1: RESUMO EXECUTIVO — pós-cirurgia completa (24/07)
A2: SP Interior = cenário real (maioria do volume). RS Capital = teste de estresse (região de MAIOR subsídio — abaixo da meta ali é efeito do frete competitivo escolhido, não erro de preço).
A4: CONTAGEM POR VEREDITO
A5: Veredito | B5: SP Interior (real) | C5: RS Capital (estresse)
A6: ACIMA DA META (>20%) | B6: 77 | C6: 36
A7: DENTRO DA META (15-20%) | B7: 36 | C7: 47
A8: ABAIXO DA META (10-15%) | B8: 0 | C8: 29
A9: CRÍTICO (<10%) | B9: 0 | C9: 1
A10: PREJUÍZO | B10: 0 | C10: 0
A12: SP INTERIOR — 12 MENORES MARGENS (todas ≥15%: catálogo 100% saudável no cenário real)
A13: SKU | B13: Margem SP | C13: Lucro/venda
A14: EMB-05 | B14: 0.16970192 | C14: 41.56
A15: L2025-B | B15: 0.17726948 | C15: 24.8
A16: Q2430-B | B16: 0.17918949 | C16: 49.08
A17: L1623-T | B17: 0.17927056 | C17: 22.217
A18: L1618-A | B18: 0.17988561 | C18: 18.87
A19: SP-PP | B19: 0.18358497 | C19: 47.543
A20: L2430-B | B20: 0.18379538 | C20: 36.397
A21: L1618-T | B21: 0.18413793 | C21: 21.36
A22: L2450-AML | B22: 0.18526356 | C22: 48.15
A23: L2430-AML | B23: 0.18568362 | C23: 34.604
A24: L2425-B | B24: 0.18622872 | C24: 34.132
A25: L2430-A | B25: 0.18718696 | C25: 33.411
A27: RS CAPITAL — 10 QUE MAIS SOFREM NO ESTRESSE (efeito do subsídio; reavaliar em 30 dias com vendas reais)
A28: SKU | B28: Margem RS | C28: Lucro/venda
A29: L1618-A | B29: 0.098856053 | C29: 10.37
A30: L1618 | B30: 0.10873269 | C30: 10.21
A31: L1623-T | B31: 0.11068345 | C31: 13.717
A32: L1618-T | B32: 0.11086207 | C32: 12.86
A33: L2025-B | B33: 0.11651179 | C33: 16.3
A34: L2025 | B34: 0.11722217 | C34: 13.259
A35: L2030 | B35: 0.12043281 | C35: 14.358
A36: L1623 | B36: 0.12147407 | C36: 13.35
A37: L1623-A | B37: 0.12671629 | C37: 15.32
A38: L2025-A | B38: 0.12775606 | C38: 16.34
A40: SP — TOP 12 MAIS LUCRATIVOS (prioridade Ads/promoções)
A41: SKU | B41: Margem SP | C41: Lucro/venda
A42: L2470-CZ | B42: 0.28158855 | C42: 100.33
A43: P3060 | B43: 0.28031364 | C43: 143.358
A44: Q3060-A | B44: 0.27866051 | C44: 161.768
...

Sheet Simulador
A1: SIMULADOR DE MARGEM v3 — CATÁLOGO COMPLETO (113 SKUs × SP Interior + RS Capital)
A2: Tarifa estimada automaticamente (célula H3 × (preço+frete)); sobrescreva com o valor real do extrato quando tiver. Cupom em 0 (pós-corte).
A3: Impostos (%): | B3: 0.1 | D3: Tarifa padrão Amazon (%):
A6: SKU | B6: Classe | C6: Região | D6: Preço de venda (R$) | E6: Cupom (%) | F6: Custo do produto (R$) | G6: Tarifa Amazon (R$) | H6: Receita pós-cupom (R$) | I6: Tarifa (%) | J6: Frete cobrado (R$) | K6: Frete real (R$) | L6: Resultado do frete (R$) | M6: Lucro líquido (R$) | N6: Margem (%) | O6: Veredito | P6: Observação
A7: EMB-03 | B7: Pequenos | C7: Rio Grande do Sul Capital | D7: 195.21 | E7: 0 | F7: 97.42 | G7: 25.04 | H7: =IF(D7="","",D7*(1-E7)) -> 195.21 | I7: =IF(OR(G7="",H7=""),"",G7/H7) -> 0.12827212 | J7: =IF(OR(B7="",C7=""),"",INDEX(Ref_Frete!$B$2:$G$54,MATCH(C7,Ref_Frete!$A$2:$A$54,0),IF(B7="Pequenos",2,IF(B7="Medios",4,6)))) -> 24.9 | K7: =IF(OR(B7="",C7=""),"",INDEX(Ref_Frete!$B$2:$G$54,MATCH(C7,Ref_Frete!$A$2:$A$54,0),IF(B7="Pequenos",1,IF(B7="Medios",3,5)))) -> 46.5 | L7: =IF(OR(J7="",K7=""),"",J7-K7) -> -21.6 | M7: =IF(OR(H7="",F7="",G7=""),"",H7-G7-F7-H7*$B$3+IF(L7="",0,L7)) -> 31.629 | N7: =IF(OR(M7="",H7=0,H7=""),"",M7/H7) -> 0.16202551 | O7: =IF(N7="","",IF(N7<0,"PREJUÍZO",IF(N7<0.1,"CRÍTICO (<10%)",IF(N7<0.15,"ABAIXO DA META (10-15%)",IF(N7<=0.2,"DENTRO DA META (15-20%)","ACIMA DA META (>20%)"))))) -> DENTRO DA META (15-20%)
A8: EMB-03 | B8: Pequenos | C8: São Paulo Interior | D8: 195.21 | E8: 0 | F8: 97.42 | G8: 25.04 | H8: =IF(D8="","",D8*(1-E8)) -> 195.21 | I8: =IF(OR(G8="",H8=""),"",G8/H8) -> 0.12827212 | J8: =IF(OR(B8="",C8=""),"",INDEX(Ref_Frete!$B$2:$G$54,MATCH(C8,Ref_Frete!$A$2:$A$54,0),IF(B8="Pequenos",2,IF(B8="Medios",4,6)))) -> 16.9 | K8: =IF(OR(B8="",C8=""),"",INDEX(Ref_Frete!$B$2:$G$54,MATCH(C8,Ref_Frete!$A$2:$A$54,0),IF(B8="Pequenos",1,IF(B8="Medios",3,5)))) -> 30 | L8: =IF(OR(J8="",K8=""),"",J8-K8) -> -13.1 | M8: =IF(OR(H8="",F8="",G8=""),"",H8-G8-F8-H8*$B$3+IF(L8="",0,L8)) -> 40.129 | N8: =IF(OR(M8="",H8=0,H8=""),"",M8/H8) -> 0.20556836 | O8: =IF(N8="","",IF(N8<0,"PREJUÍZO",IF(N8<0.1,"CRÍTICO (<10%)",IF(N8<0.15,"ABAIXO DA META (10-15%)",IF(N8<=0.2,"DENTRO DA META (15-20%)","ACIMA DA META (>20%)"))))) -> ACIMA DA META (>20%)
A9: EMB-03P | B9: Pequenos | C9: Rio Grande do Sul Capital | D9: 245.9 | E9: 0 | F9: 127.42 | G9: 31.41 | H9: =IF(D9="","",D9*(1-E9)) -> 245.9 | I9: =IF(OR(G9="",H9=""),"",G9/H9) -> 0.12773485 | J9: =IF(OR(B9="",C9=""),"",INDEX(Ref_Frete!$B$2:$G$54,MATCH(C9,Ref_Frete!$A$2:$A$54,0),IF(B9="Pequenos",2,IF(B9="Medios",4,6)))) -> 24.9 | K9: =IF(OR(B9="",C9=""),"",INDEX(Ref_Frete!$B$2:$G$54,MATCH(C9,Ref_Frete!$A$2:$A$54,0),IF(B9="Pequenos",1,IF(B9="Medios",3,5)))) -> 46.5 | L9: =IF(OR(J9="",K9=""),"",J9-K9) -> -21.6 | M9: =IF(OR(H9="",F9="",G9=""),"",H9-G9-F9-H9*$B$3+IF(L9="",0,L9)) -> 40.88 | N9: =IF(OR(M9="",H9=0,H9=""),"",M9/H9) -> 0.16624644 | O9: =IF(N9="","",IF(N9<0,"PREJUÍZO",IF(N9<0.1,"CRÍTICO (<10%)",IF(N9<0.15,"ABAIXO DA META (10-15%)",IF(N9<=0.2,"DENTRO DA META (15-20%)","ACIMA DA META (>20%)"))))) -> DENTRO DA META (15-20%) | P9: Preço +R$50 conforme instrução Dianna. Custo 127,42 = estimativa (+30 s/ polida) — confirmar custo REAL da pintura com produção
A10: EMB-03P | B10: Pequenos | C10: São Paulo Interior | D10: 245.9 | E10: 0 | F10: 127.42 | G10: 31.41 | H10: =IF(D10="","",D10*(1-E10)) -> 245.9 | I10: =IF(OR(G10="",H10=""),"",G10/H10) -> 0.12773485 | J10: =IF(OR(B10="",C10=""),"",INDEX(Ref_Frete!$B$2:$G$54,MATCH(C10,Ref_Frete!$A$2:$A$54,0),IF(B10="Pequenos",2,IF(B10="Medios",4,6)))) -> 16.9 | K10: =IF(OR(B10="",C10=""),"",INDEX(Ref_Frete!$B$2:$G$54,MATCH(C10,Ref_Frete!$A$2:$A$54,0),IF(B10="Pequenos",1,IF(B10="Medios",3,5)))) -> 30 | L10: =IF(OR(J10="",K10=""),"",J10-K10) -> -13.1 | M10: =IF(OR(H10="",F10="",G10=""),"",H10-G10-F10-H10*$B$3+IF(L10="",0,L10)) -> 49.38 | N10: =IF(OR(M10="",H10=0,H10=""),"",M10/H10) -> 0.20081334 | O10: =IF(N10="","",IF(N10<0,"PREJUÍZO",IF(N10<0.1,"CRÍTICO (<10%)",IF(N10<0.15,"ABAIXO DA META (10-15%)",IF(N10<=0.2,"DENTRO DA META (15-20%)","ACIMA DA META (>20%)"))))) -> ACIMA DA META (>20%) | P10: Preço +R$50 conforme instrução Dianna. Custo 127,42 = estimativa (+30 s/ polida) — confirmar custo REAL da pintura com produção
A11: EMB-05 | B11: Pequenos | C11: Rio Grande do Sul Capital | D11: 244.9 | E11: 0 | F11: 134.46 | G11: 31.29 | H11: =IF(D11="","",D11*(1-E11)) -> 244.9 | I11: =IF(OR(G11="",H11=""),"",G11/H11) -> 0.12776644 | J11: =IF(OR(B11="",C11=""),"",INDEX(Ref_Frete!$B$2:$G$54,MATCH(C11,Ref_Frete!$A$2:$A$54,0),IF(B11="Pequenos",2,IF(B11="Medios",4,6)))) -> 24.9 | K11: =IF(OR(B11="",C11=""),"",INDEX(Ref_Frete!$B$2:$G$54,MATCH(C11,Ref_Frete!$A$2:$A$54,0),IF(B11="Pequenos",1,IF(B11="Medios",3,5)))) -> 46.5 | L11: =IF(OR(J11="",K11=""),"",J11-K11) -> -21.6 | M11: =IF(OR(H11="",F11="",G11=""),"",H11-G11-F11-H11*$B$3+IF(L11="",0,L11)) -> 33.06 | N11: =IF(OR(M11="",H11=0,H11=""),"",M11/H11) -> 0.13499388 | O11: =IF(N11="","",IF(N11<0,"PREJUÍZO",IF(N11<0.1,"CRÍTICO (<10%)",IF(N11<0.15,"ABAIXO DA META (10-15%)",IF(N11<=0.2,"DENTRO DA META (15-20%)","ACIMA DA META (>20%)"))))) -> ABAIXO DA META (10-15%)
A12: EMB-05 | B12: Pequenos | C12: São Paulo Interior | D12: 244.9 | E12: 0 | F12: 134.46 | G12: 31.29 | H12: =IF(D12="","",D12*(1-E12)) -> 244.9 | I12: =IF(OR(G12="",H12=""),"",G12/H12) -> 0.12776644 | J12: =IF(OR(B12="",C12=""),"",INDEX(Ref_Frete!$B$2:$G$54,MATCH(C12,Ref_Frete!$A$2:$A$54,0),IF(B12="Pequenos",2,IF(B12="Medios",4,6)))) -> 16.9 | K12: =IF(OR(B12="",C12=""),"",INDEX(Ref_Frete!$B$2:$G$54,MATCH(C12,Ref_Frete!$A$2:$A$54,0),IF(B12="Pequenos",1,IF(B12="Medios",3,5)))) -> 30 | L12: =IF(OR(J12="",K12=""),"",J12-K12) -> -13.1 | M12: =IF(OR(H12="",F12="",G12=""),"",H12-G12-F12-H12*$B$3+IF(L12="",0,L12)) -> 41.56 | N12: =IF(OR(M12="",H12=0,H12=""),"",M12/H12) -> 0.16970192 | O12: =IF(N12="","",IF(N12<0,"PREJUÍZO",IF(N12<0.1,"CRÍTICO (<10%)",IF(N12<0.15,"ABAIXO DA META (10-15%)",IF(N12<=0.2,"DENTRO DA META (15-20%)","ACIMA DA META (>20%)"))))) -> DENTRO DA META (15-20%)
A13: EMB-05P | B13: Pequenos | C13: Rio Grande do Sul Capital | D13: 290 | E13: 0 | F13: 154.46 | G13: 36.92 | H13: =IF(D13="","",D13*(1-E13)) -> 290 | I13: =IF(OR(G13="",H13=""),"",G13/H13) -> 0.12731034 | J13: =IF(OR(B13="",C13=""),"",INDEX(Ref_Frete!$B$2:$G$54,MATCH(C13,Ref_Frete!$A$2:$A$54,0),IF(B13="Pequenos",2,IF(B13="Medios",4,6)))) -> 24.9 | K13: =IF(OR(B13="",C13=""),"",INDEX(Ref_Frete!$B$2:$G$54,MATCH(C13,Ref_Frete!$A$2:$A$54,0),IF(B13="Pequenos",1,IF(B13="Medios",3,5)))) -> 46.5 | L13: =IF(OR(J13="",K13=""),"",J13-K13) -> -21.6 | M13: =IF(OR(H13="",F13="",G13=""),"",H13-G13-F13-H13*$B$3+IF(L13="",0,L13)) -> 48.02 | N13: =IF(OR(M13="",H13=0,H13=""),"",M13/H13) -> 0.16558621 | O13: =IF(N13="","",IF(N13<0,"PREJUÍZO",IF(N13<0.1,"CRÍTICO (<10%)",IF(N13<0.15,"ABAIXO DA META (10-15%)",IF(N13<=0.2,"DENTRO DA META (15-20%)","ACIMA DA META (>20%)"))))) -> DENTRO DA META (15-20%) | P13: Preço +R$50 conforme instrução Dianna. Custo 154,46 = estimativa (+20 s/ polida) — confirmar custo REAL da pintura com produção
A14: EMB-05P | B14: Pequenos | C14: São Paulo Interior | D14: 290 | E14: 0 | F14: 154.46 | G14: 36.92 | H14: =IF(D14="","",D14*(1-E14)) -> 290 | I14: =IF(OR(G14="",H14=""),"",G14/H14) -> 0.12731034 | J14: =IF(OR(B14="",C14=""),"",INDEX(Ref_Frete!$B$2:$G$54,MATCH(C14,Ref_Frete!$A$2:$A$54,0),IF(B14="Pequenos",2,IF(B14="Medios",4,6)))) -> 16.9 | K14: =IF(OR(B14="",C14=""),"",INDEX(Ref_Frete!$B$2:$G$54,MATCH(C14,Ref_Frete!$A$2:$A$54,0),IF(B14="Pequenos",1,IF(B14="Medios",3,5)))) -> 30 | L14: =IF(OR(J14="",K14=""),"",J14-K14) -> -13.1 | M14: =IF(OR(H14="",F14="",G14=""),"",H14-G14-F14-H14*$B$3+IF(L14="",0,L14)) -> 56.52 | N14: =IF(OR(M14="",H14=0,H14=""),"",M14/H14) -> 0.19489655 | O14: =IF(N14="","",IF(N14<0,"PREJUÍZO",IF(N14<0.1,"CRÍTICO (<10%)",IF(N14<0.15,"ABAIXO DA META (10-15%)",IF(N14<=0.2,"DENTRO DA META (15-20%)","ACIMA DA META (>20%)"))))) -> DENTRO DA META (15-20%) | P14: Preço +R$50 conforme instrução Dianna. Custo 154,46 = estimativa (+20 s/ polida) — confirmar custo REAL da pintura com produção
A15: EMB-08 | B15: Pequenos | C15: Rio Grande do Sul Capital | D15: 344.76 | E15: 0 | F15: 181.23 | G15: 42.92 | H15: =IF(D15="","",D15*(1-E15)) -> 344.76 | I15: =IF(OR(G15="",H15=""),"",G15/H15) -> 0.1244924 | J15: =IF(OR(B15="",C15=""),"",INDEX(Ref_Frete!$B$2:$G$54,MATCH(C15,Ref_Frete!$A$2:$A$54,0),IF(B15="Pequenos",2,IF(B15="Medios",4,6)))) -> 24.9 | K15: =IF(OR(B15="",C15=""),"",INDEX(Ref_Frete!$B$2:$G$54,MATCH(C15,Ref_Frete!$A$2:$A$54,0),IF(B15="Pequenos",1,IF(B15="Medios",3,5)))) -> 46.5 | L15: =IF(OR(J15="",K15=""),"",J15-K15) -> -21.6 | M15: =IF(OR(H15="",F15="",G15=""),"",H15-G15-F15-H15*$B$3+IF(L15="",0,L15)) -> 64.534 | N15: =IF(OR(M15="",H15=0,H15=""),"",M15/H15) -> 0.18718529 | O15: =IF(N15="","",IF(N15<0,"PREJUÍZO",IF(N15<0.1,"CRÍTICO (<10%)",IF(N15<0.15,"ABAIXO DA META (10-15%)",IF(N15<=0.2,"DENTRO DA META (15-20%)","ACIMA DA META (>20%)"))))) -> DENTRO DA META (15-20%)
A16: EMB-08 | B16: Pequenos | C16: São Paulo Interior | D16: 344.76 | E16: 0 | F16: 181.23 | G16: 42.92 | H16: =IF(D16="","",D16*(1-E16)) -> 344.76 | I16: =IF(OR(G16="",H16=""),"",G16/H16) -> 0.1244924 | J16: =IF(OR(B16="",C16=""),"",INDEX(Ref_Frete!$B$2:$G$54,MATCH(C16,Ref_Frete!$A$2:$A$54,0),IF(B16="Pequenos",2,IF(B16="Medios",4,6)))) -> 16.9 | K16: =IF(OR(B16="",C16=""),"",INDEX(Ref_Frete!$B$2:$G$54,MATCH(C16,Ref_Frete!$A$2:$A$54,0),IF(B16="Pequenos",1,IF(B16="Medios",3,5)))) -> 30 | L16: =IF(OR(J16="",K16=""),"",J16-K16) -> -13.1 | M16: =IF(OR(H16="",F16="",G16=""),"",H16-G16-F16-H16*$B$3+IF(L16="",0,L16)) -> 73.034 | N16: =IF(OR(M16="",H16=0,H16=""),"",M16/H16) -> 0.21184012 | O16: =IF(N16="","",IF(N16<0,"PREJUÍZO",IF(N16<0.1,"CRÍTICO (<10%)",IF(N16<0.15,"ABAIXO DA META (10-15%)",IF(N16<=0.2,"DENTRO DA META (15-20%)","ACIMA DA META (>20%)"))))) -> ACIMA DA META (>20%)
A17: L1618 | B17: Pequenos | C17: Rio Grande do Sul Capital | D17: 93.9 | E17: 0 | F17: 39.8 | G17: 12.9 | H17: =IF(D17="","",D17*(1-E17)) -> 93.9 | I17: =IF(OR(G17="",H17=""),"",G17/H17) -> 0.13738019 | J17: =IF(OR(B17="",C17=""),"",INDEX(Ref_Frete!$B$2:$G$54,MATCH(C17,Ref_Frete!$A$2:$A$54,0),IF(B17="Pequenos",2,IF(B17="Medios",4,6)))) -> 24.9 | K17: =IF(OR(B17="",C17=""),"",INDEX(Ref_Frete!$B$2:$G$54,MATCH(C17,Ref_Frete!$A$2:$A$54,0),IF(B17="Pequenos",1,IF(B17="Medios",3,5)))) -> 46.5 | L17: =IF(OR(J17="",K17=""),"",J17-K17) -> -21.6 | M17: =IF(OR(H17="",F17="",G17=""),"",H17-G17-F17-H17*$B$3+IF(L17="",0,L17)) -> 10.21 | N17: =IF(OR(M17="",H17=0,H17=""),"",M17/H17) -> 0.10873269 | O17: =IF(N17="","",IF(N17<0,"PREJUÍZO",IF(N17<0.1,"CRÍTICO (<10%)",IF(N17<0.15,"ABAIXO DA META (10-15%)",IF(N17<=0.2,"DENTRO DA META (15-20%)","ACIMA DA META (>20%)"))))) -> ABAIXO DA META (10-15%)
A18: L1618 | B18: Pequenos | C18: São Paulo Interior | D18: 93.9 | E18: 0 | F18: 39.8 | G18: 12.9 | H18: =IF(D18="","",D18*(1-E18)) -> 93.9 | I18: =IF(OR(G18="",H18=""),"",G18/H18) -> 0.13738019 | J18: =IF(OR(B18="",C18=""),"",INDEX(Ref_Frete!$B$2:$G$54,MATCH(C18,Ref_Frete!$A$2:$A$54,0),IF(B18="Pequenos",2,IF(B18="Medios",4,6)))) -> 16.9 | K18: =IF(OR(B18="",C18=""),"",INDEX(Ref_Frete!$B$2:$G$54,MATCH(C18,Ref_Frete!$A$2:$A$54,0),IF(B18="Pequenos",1,IF(B18="Medios",3,5)))) -> 30 | L18: =IF(OR(J18="",K18=""),"",J18-K18) -> -13.1 | M18: =IF(OR(H18="",F18="",G18=""),"",H18-G18-F18-H18*$B$3+IF(L18="",0,L18)) -> 18.71 | N18: =IF(OR(M18="",H18=0,H18=""),"",M18/H18) -> 0.19925453 | O18: =IF(N18="","",IF(N18<0,"PREJUÍZO",IF(N18<0.1,"CRÍTICO (<10%)",IF(N18<0.15,"ABAIXO DA META (10-15%)",IF(N18<=0.2,"DENTRO DA META (15-20%)","ACIMA DA META (>20%)"))))) -> DENTRO DA META (15-20%)
A19: L1618-A | B19: Pequenos | C19: Rio Grande do Sul Capital | D19: 104.9 | E19: 0 | F19: 48.18 | G19: 14.26 | H19: =IF(D19="","",D19*(1-E19)) -> 104.9 | I19: =IF(OR(G19="",H19=""),"",G19/H19) -> 0.13593899 | J19: =IF(OR(B19="",C19=""),"",INDEX(Ref_Frete!$B$2:$G$54,MATCH(C19,Ref_Frete!$A$2:$A$54,0),IF(B19="Pequenos",2,IF(B19="Medios",4,6)))) -> 24.9 | K19: =IF(OR(B19="",C19=""),"",INDEX(Ref_Frete!$B$2:$G$54,MATCH(C19,Ref_Frete!$A$2:$A$54,0),IF(B19="Pequenos",1,IF(B19="Medios",3,5)))) -> 46.5 | L19: =IF(OR(J19="",K19=""),"",J19-K19) -> -21.6 | M19: =IF(OR(H19="",F19="",G19=""),"",H19-G19-F19-H19*$B$3+IF(L19="",0,L19)) -> 10.37 | N19: =IF(OR(M19="",H19=0,H19=""),"",M19/H19) -> 0.098856053 | O19: =IF(N19="","",IF(N19<0,"PREJUÍZO",IF(N19<0.1,"CRÍTICO (<10%)",IF(N19<0.15,"ABAIXO DA META (10-15%)",IF(N19<=0.2,"DENTRO DA META (15-20%)","ACIMA DA META (>20%)"))))) -> CRÍTICO (<10%)
A20: L1618-A | B20: Pequenos | C20: São Paulo Interior | D20: 104.9 | E20: 0 | F20: 48.18 | G20: 14.26 | H20: =IF(D20="","",D20*(1-E20)) -> 104.9 | I20: =IF(OR(G20="",H20=""),"",G20/H20) -> 0.13593899 | J20: =IF(OR(B20="",C20=""),"",INDEX(Ref_Frete!$B$2:$G$54,MATCH(C20,Ref_Frete!$A$2:$A$54,0),IF(B20="Pequenos",2,IF(B20="Medios",4,6)))) -> 16.9 | K20: =IF(OR(B20="",C20=""),"",INDEX(Ref_Frete!$B$2:$G$54,MATCH(C20,Ref_Frete!$A$2:$A$54,0),IF(B20="Pequenos",1,IF(B20="Medios",3,5)))) -> 30 | L20: =IF(OR(J20="",K20=""),"",J20-K20) -> -13.1 | M20: =IF(OR(H20="",F20="",G20=""),"",H20-G20-F20-H20*$B$3+IF(L20="",0,L20)) -> 18.87 | N20: =IF(OR(M20="",H20=0,H20=""),"",M20/H20) -> 0.17988561 | O20: =IF(N20="","",IF(N20<0,"PREJUÍZO",IF(N20<0.1,"CRÍTICO (<10%)",IF(N20<0.15,"ABAIXO DA META (10-15%)",IF(N20<=0.2,"DENTRO DA META (15-20%)","ACIMA DA META (>20%)"))))) -> DENTRO DA META (15-20%)
A21: L1618-B | B21: Pequenos | C21: Rio Grande do Sul Capital | D21: 129.9 | E21: 0 | F21: 60.62 | G21: 17.22 | H21: =IF(D21="","",D21*(1-E21)) -> 129.9 | I21: =IF(OR(G21="",H21=""),"",G21/H21) -> 0.13256351 | J21: =IF(OR(B21="",C21=""),"",INDEX(Ref_Frete!$B$2:$G$54,MATCH(C21,Ref_Frete!$A$2:$A$54,0),IF(B21="Pequenos",2,IF(B21="Medios",4,6)))) -> 24.9 | K21: =IF(OR(B21="",C21=""),"",INDEX(Ref_Frete!$B$2:$G$54,MATCH(C21,Ref_Frete!$A$2:$A$54,0),IF(B21="Pequenos",1,IF(B21="Medios",3,5)))) -> 46.5 | L21: =IF(OR(J21="",K21=""),"",J21-K21) -> -21.6 | M21: =IF(OR(H21="",F21="",G21=""),"",H21-G21-F21-H21*$B$3+IF(L21="",0,L21)) -> 17.47 | N21: =IF(OR(M21="",H21=0,H21=""),"",M21/H21) -> 0.13448807 | O21: =IF(N21="","",IF(N21<0,"PREJUÍZO",IF(N21<0.1,"CRÍTICO (<10%)",IF(N21<0.15,"ABAIXO DA META (10-15%)",IF(N21<=0.2,"DENTRO DA META (15-20%)","ACIMA DA META (>20%)"))))) -> ABAIXO DA META (10-15%)
A22: L1618-B | B22: Pequenos | C22: São Paulo Interior | D22: 129.9 | E22: 0 | F22: 60.62 | G22: 17.22 | H22: =IF(D22="","",D22*(1-E22)) -> 129.9 | I22: =IF(OR(G22="",H22=""),"",G22/H22) -> 0.13256351 | J22: =IF(OR(B22="",C22=""),"",INDEX(Ref_Frete!$B$2:$G$54,MATCH(C22,Ref_Frete!$A$2:$A$54,0),IF(B22="Pequenos",2,IF(B22="Medios",4,6)))) -> 16.9 | K22: =IF(OR(B22="",C22=""),"",INDEX(Ref_Frete!$B$2:$G$54,MATCH(C22,Ref_Frete!$A$2:$A$54,0),IF(B22="Pequenos",1,IF(B22="Medios",3,5)))) -> 30 | L22: =IF(OR(J22="",K22=""),"",J22-K22) -> -13.1 | M22: =IF(OR(H22="",F22="",G22=""),"",H22-G22-F22-H22*$B$3+IF(L22="",0,L22)) -> 25.97 | N22: =IF(OR(M22="",H22=0,H22=""),"",M22/H22) -> 0.19992302 | O22: =IF(N22="","",IF(N22<0,"PREJUÍZO",IF(N22<0.1,"CRÍTICO (<10%)",IF(N22<0.15,"ABAIXO DA META (10-15%)",IF(N22<=0.2,"DENTRO DA META (15-20%)","ACIMA DA META (>20%)"))))) -> DENTRO DA META (15-20%)
A23: L1618-T | B23: Pequenos | C23: Rio Grande do Sul Capital | D23: 116 | E23: 0 | F23: 54.47 | G23: 15.47 | H23: =IF(D23="","",D23*(1-E23)) -> 116 | I23: =IF(OR(G23="",H23=""),"",G23/H23) -> 0.13336207 | J23: =IF(OR(B23="",C23=""),"",INDEX(Ref_Frete!$B$2:$G$54,MATCH(C23,Ref_Frete!$A$2:$A$54,0),IF(B23="Pequenos",2,IF(B23="Medios",4,6)))) -> 24.9 | K23: =IF(OR(B23="",C23=""),"",INDEX(Ref_Frete!$B$2:$G$54,MATCH(C23,Ref_Frete!$A$2:$A$54,0),IF(B23="Pequenos",1,IF(B23="Medios",3,5)))) -> 46.5 | L23: =IF(OR(J23="",K23=""),"",J23-K23) -> -21.6 | M23: =IF(OR(H23="",F23="",G23=""),"",H23-G23-F23-H23*$B$3+IF(L23="",0,L23)) -> 12.86 | N23: =IF(OR(M23="",H23=0,H23=""),"",M23/H23) -> 0.11086207 | O23: =IF(N23="","",IF(N23<0,"PREJUÍZO",IF(N23<0.1,"CRÍTICO (<10%)",IF(N23<0.15,"ABAIXO DA META (10-15%)",IF(N23<=0.2,"DENTRO DA META (15-20%)","ACIMA DA META (>20%)"))))) -> ABAIXO DA META (10-15%)
A24: L1618-T | B24: Pequenos | C24: São Paulo Interior | D24: 116 | E24: 0 | F24: 54.47 | G24: 15.47 | H24: =IF(D24="","",D24*(1-E24)) -> 116 | I24: =IF(OR(G24="",H24=""),"",G24/H24) -> 0.13336207 | J24: =IF(OR(B24="",C24=""),"",INDEX(Ref_Frete!$B$2:$G$54,MATCH(C24,Ref_Frete!$A$2:$A$54,0),IF(B24="Pequenos",2,IF(B24="Medios",4,6)))) -> 16.9 | K24: =IF(OR(B24="",C24=""),"",INDEX(Ref_Frete!$B$2:$G$54,MATCH(C24,Ref_Frete!$A$2:$A$54,0),IF(B24="Pequenos",1,IF(B24="Medios",3,5)))) -> 30 | L24: =IF(OR(J24="",K24=""),"",J24-K24) -> -13.1 | M24: =IF(OR(H24="",F24="",G24=""),"",H24-G24-F24-H24*$B$3+IF(L24="",0,L24)) -> 21.36 | N24: =IF(OR(M24="",H24=0,H24=""),"",M24/H24) -> 0.18413793 | O24: =IF(N24="","",IF(N24<0,"PREJUÍZO",IF(N24<0.1,"CRÍTICO (<10%)",IF(N24<0.15,"ABAIXO DA META (10-15%)",IF(N24<=0.2,"DENTRO DA META (15-20%)","ACIMA DA META (>20%)"))))) -> DENTRO DA META (15-20%)
A25: L1623 | B25: Pequenos | C25: Rio Grande do Sul Capital | D25: 109.9 | E25: 0 | F25: 49.15 | G25: 14.81 | H25: =IF(D25="","",D25*(1-E25)) -> 109.9 | I25: =IF(OR(G25="",H25=""),"",G25/H25) -> 0.13475887 | J25: =IF(OR(B25="",C25=""),"",INDEX(Ref_Frete!$B$2:$G$54,MATCH(C25,Ref_Frete!$A$2:$A$54,0),IF(B25="Pequenos",2,IF(B25="Medios",4,6)))) -> 24.9 | K25: =IF(OR(B25="",C25=""),"",INDEX(Ref_Frete!$B$2:$G$54,MATCH(C25,Ref_Frete!$A$2:$A$54,0),IF(B25="Pequenos",1,IF(B25="Medios",3,5)))) -> 46.5 | L25: =IF(OR(J25="",K25=""),"",J25-K25) -> -21.6 | M25: =IF(OR(H25="",F25="",G25=""),"",H25-G25-F25-H25*$B$3+IF(L25="",0,L25)) -> 13.35 | N25: =IF(OR(M25="",H25=0,H25=""),"",M25/H25) -> 0.12147407 | O25: =IF(N25="","",IF(N25<0,"PREJUÍZO",IF(N25<0.1,"CRÍTICO (<10%)",IF(N25<0.15,"ABAIXO DA META (10-15%)",IF(N25<=0.2,"DENTRO DA META (15-20%)","ACIMA DA META (>20%)"))))) -> ABAIXO DA META (10-15%)
A26: L1623 | B26: Pequenos | C26: São Paulo Interior | D26: 109.9 | E26: 0 | F26: 49.15 | G26: 14.81 | H26: =IF(D26="","",D26*(1-E26)) -> 109.9 | I26: =IF(OR(G26="",H26=""),"",G26/H26) -> 0.13475887 | J26: =IF(OR(B26="",C26=""),"",INDEX(Ref_Frete!$B$2:$G$54,MATCH(C26,Ref_Frete!$A$2:$A$54,0),IF(B26="Pequenos",2,IF(B26="Medios",4,6)))) -> 16.9 | K26: =IF(OR(B26="",C26=""),"",INDEX(Ref_Frete!$B$2:$G$54,MATCH(C26,Ref_Frete!$A$2:$A$54,0),IF(B26="Pequenos",1,IF(B26="Medios",3,5)))) -> 30 | L26: =IF(OR(J26="",K26=""),"",J26-K26) -> -13.1 | M26: =IF(OR(H26="",F26="",G26=""),"",H26-G26-F26-H26*$B$3+IF(L26="",0,L26)) -> 21.85 | N26: =IF(OR(M26="",H26=0,H26=""),"",M26/H26) -> 0.19881711 | O26: =IF(N26="","",IF(N26<0,"PREJUÍZO",IF(N26<0.1,"CRÍTICO (<10%)",IF(N26<0.15,"ABAIXO DA META (10-15%)",IF(N26<=0.2,"DENTRO DA META (15-20%)","ACIMA DA META (>20%)"))))) -> DENTRO DA META (15-20%)
... A96: Q2430-B | B96: Pequenos | C96: São Paulo Interior | D96: 273.9 | E96: 0 | F96: 149.88 | G96: 34.45 | H96: =IF(D96="","",D96*(1-E96)) -> 273.9 | I96: =IF(OR(G96="",H96=""),"",G96/H96) -> 0.12577583 | J96: =IF(OR(B96="",C96=""),"",INDEX(Ref_Frete!$B$2:$G$54,MATCH(C96,Ref_Frete!$A$2:$A$54,0),IF(B96="Pequenos",2,IF(B96="Medios",4,6)))) -> 16.9 | K96: =IF(OR(B96="",C96=""),"",INDEX(Ref_Frete!$B$2:$G$54,MATCH(C96,Ref_Frete!$A$2:$A$54,0),IF(B96="Pequenos",1,IF(B96="Medios",3,5)))) -> 30 | L96: =IF(OR(J96="",K96=""),"",J96-K96) -> -13.1 | M96: =IF(OR(H96="",F96="",G96=""),"",H96-G96-F96-H96*$B$3+IF(L96="",0,L96)) -> 49.08 | N96: =IF(OR(M96="",H96=0,H96=""),"",M96/H96) -> 0.17918949 | O96: =IF(N96="","",IF(N96<0,"PREJUÍZO",IF(N96<0.1,"CRÍTICO (<10%)",IF(N96<0.15,"ABAIXO DA META (10-15%)",IF(N96<=0.2,"DENTRO DA META (15-20%)","ACIMA DA META (>20%)"))))) -> DENTRO DA META (15-20%)
A97: SP-PP | B97: Pequenos | C97: Rio Grande do Sul Capital | D97: 258.97 | E97: 0 | F97: 139.81 | G97: 32.62 | H97: =IF(D97="","",D97*(1-E97)) -> 258.97 | I97: =IF(OR(G97="",H97=""),"",G97/H97) -> 0.12596054 | J97: =IF(OR(B97="",C97=""),"",INDEX(Ref_Frete!$B$2:$G$54,MATCH(C97,Ref_Frete!$A$2:$A$54,0),IF(B97="Pequenos",2,IF(B97="Medios",4,6)))) -> 24.9 | K97: =IF(OR(B97="",C97=""),"",INDEX(Ref_Frete!$B$2:$G$54,MATCH(C97,Ref_Frete!$A$2:$A$54,0),IF(B97="Pequenos",1,IF(B97="Medios",3,5)))) -> 46.5 | L97: =IF(OR(J97="",K97=""),"",J97-K97) -> -21.6 | M97: =IF(OR(H97="",F97="",G97=""),"",H97-G97-F97-H97*$B$3+IF(L97="",0,L97)) -> 39.043 | N97: =IF(OR(M97="",H97=0,H97=""),"",M97/H97) -> 0.15076264 | O97: =IF(N97="","",IF(N97<0,"PREJUÍZO",IF(N97<0.1,"CRÍTICO (<10%)",IF(N97<0.15,"ABAIXO DA META (10-15%)",IF(N97<=0.2,"DENTRO DA META (15-20%)","ACIMA DA META (>20%)"))))) -> DENTRO DA META (15-20%) | P97: Conferir: Amazon=Pequenos, classificação v4 indicava Medios (~7,5 kg cubado)
A98: SP-PP | B98: Pequenos | C98: São Paulo Interior | D98: 258.97 | E98: 0 | F98: 139.81 | G98: 32.62 | H98: =IF(D98="","",D98*(1-E98)) -> 258.97 | I98: =IF(OR(G98="",H98=""),"",G98/H98) -> 0.12596054 | J98: =IF(OR(B98="",C98=""),"",INDEX(Ref_Frete!$B$2:$G$54,MATCH(C98,Ref_Frete!$A$2:$A$54,0),IF(B98="Pequenos",2,IF(B98="Medios",4,6)))) -> 16.9 | K98: =IF(OR(B98="",C98=""),"",INDEX(Ref_Frete!$B$2:$G$54,MATCH(C98,Ref_Frete!$A$2:$A$54,0),IF(B98="Pequenos",1,IF(B98="Medios",3,5)))) -> 30 | L98: =IF(OR(J98="",K98=""),"",J98-K98) -> -13.1 | M98: =IF(OR(H98="",F98="",G98=""),"",H98-G98-F98-H98*$B$3+IF(L98="",0,L98)) -> 47.543 | N98: =IF(OR(M98="",H98=0,H98=""),"",M98/H98) -> 0.18358497 | O98: =IF(N98="","",IF(N98<0,"PREJUÍZO",IF(N98<0.1,"CRÍTICO (<10%)",IF(N98<0.15,"ABAIXO DA META (10-15%)",IF(N98<=0.2,"DENTRO DA META (15-20%)","ACIMA DA META (>20%)"))))) -> DENTRO DA META (15-20%) | P98: Conferir: Amazon=Pequenos, classificação v4 indicava Medios (~7,5 kg cubado)
A99: EGC | B99: Medios | C99: Rio Grande do Sul Capital | D99: 674.62 | E99: 0 | F99: 365.7 | G99: 85.14 | H99: =IF(D99="","",D99*(1-E99)) -> 674.62 | I99: =IF(OR(G99="",H99=""),"",G99/H99) -> 0.12620438 | J99: =IF(OR(B99="",C99=""),"",INDEX(Ref_Frete!$B$2:$G$54,MATCH(C99,Ref_Frete!$A$2:$A$54,0),IF(B99="Pequenos",2,IF(B99="Medios",4,6)))) -> 59.9 | K99: =IF(OR(B99="",C99=""),"",INDEX(Ref_Frete!$B$2:$G$54,MATCH(C99,Ref_Frete!$A$2:$A$54,0),IF(B99="Pequenos",1,IF(B99="Medios",3,5)))) -> 89 | L99: =IF(OR(J99="",K99=""),"",J99-K99) -> -29.1 | M99: =IF(OR(H99="",F99="",G99=""),"",H99-G99-F99-H99*$B$3+IF(L99="",0,L99)) -> 127.218 | N99: =IF(OR(M99="",H99=0,H99=""),"",M99/H99) -> 0.18857727 | O99: =IF(N99="","",IF(N99<0,"PREJUÍZO",IF(N99<0.1,"CRÍTICO (<10%)",IF(N99<0.15,"ABAIXO DA META (10-15%)",IF(N99<=0.2,"DENTRO DA META (15-20%)","ACIMA DA META (>20%)"))))) -> DENTRO DA META (15-20%)
A100: EGC | B100: Medios | C100: São Paulo Interior | D100: 674.62 | E100: 0 | F100: 365.7 | G100: 85.14 | H100: =IF(D100="","",D100*(1-E100)) -> 674.62 | I100: =IF(OR(G100="",H100=""),"",G100/H100) -> 0.12620438 | J100: =IF(OR(B100="",C100=""),"",INDEX(Ref_Frete!$B$2:$G$54,MATCH(C100,Ref_Frete!$A$2:$A$54,0),IF(B100="Pequenos",2,IF(B100="Medios",4,6)))) -> 39.9 | K100: =IF(OR(B100="",C100=""),"",INDEX(Ref_Frete!$B$2:$G$54,MATCH(C100,Ref_Frete!$A$2:$A$54,0),IF(B100="Pequenos",1,IF(B100="Medios",3,5)))) -> 49 | L100: =IF(OR(J100="",K100=""),"",J100-K100) -> -9.1 | M100: =IF(OR(H100="",F100="",G100=""),"",H100-G100-F100-H100*$B$3+IF(L100="",0,L100)) -> 147.218 | N100: =IF(OR(M100="",H100=0,H100=""),"",M100/H100) -> 0.21822359 | O100: =IF(N100="","",IF(N100<0,"PREJUÍZO",IF(N100<0.1,"CRÍTICO (<10%)",IF(N100<0.15,"ABAIXO DA META (10-15%)",IF(N100<=0.2,"DENTRO DA META (15-20%)","ACIMA DA META (>20%)"))))) -> ACIMA DA META (>20%)
A101: L2460-A | B101: Medios | C101: Rio Grande do Sul Capital | D101: 272.57 | E101: 0 | F101: 136.09 | G101: 36.9 | H101: =IF(D101="","",D101*(1-E101)) -> 272.57 | I101: =IF(OR(G101="",H101=""),"",G101/H101) -> 0.13537807 | J101: =IF(OR(B101="",C101=""),"",INDEX(Ref_Frete!$B$2:$G$54,MATCH(C101,Ref_Frete!$A$2:$A$54,0),IF(B101="Pequenos",2,IF(B101="Medios",4,6)))) -> 59.9 | K101: =IF(OR(B101="",C101=""),"",INDEX(Ref_Frete!$B$2:$G$54,MATCH(C101,Ref_Frete!$A$2:$A$54,0),IF(B101="Pequenos",1,IF(B101="Medios",3,5)))) -> 89 | L101: =IF(OR(J101="",K101=""),"",J101-K101) -> -29.1 | M101: =IF(OR(H101="",F101="",G101=""),"",H101-G101-F101-H101*$B$3+IF(L101="",0,L101)) -> 43.223 | N101: =IF(OR(M101="",H101=0,H101=""),"",M101/H101) -> 0.15857578 | O101: =IF(N101="","",IF(N101<0,"PREJUÍZO",IF(N101<0.1,"CRÍTICO (<10%)",IF(N101<0.15,"ABAIXO DA META (10-15%)",IF(N101<=0.2,"DENTRO DA META (15-20%)","ACIMA DA META (>20%)"))))) -> DENTRO DA META (15-20%)
A102: L2460-A | B102: Medios | C102: São Paulo Interior | D102: 272.57 | E102: 0 | F102: 136.09 | G102: 36.9 | H102: =IF(D102="","",D102*(1-E102)) -> 272.57 | I102: =IF(OR(G102="",H102=""),"",G102/H102) -> 0.13537807 | J102: =IF(OR(B102="",C102=""),"",INDEX(Ref_Frete!$B$2:$G$54,MATCH(C102,Ref_Frete!$A$2:$A$54,0),IF(B102="Pequenos",2,IF(B102="Medios",4,6)))) -> 39.9 | K102: =IF(OR(B102="",C102=""),"",INDEX(Ref_Frete!$B$2:$G$54,MATCH(C102,Ref_Frete!$A$2:$A$54,0),IF(B102="Pequenos",1,IF(B102="Medios",3,5)))) -> 49 | L102: =IF(OR(J102="",K102=""),"",J102-K102) -> -9.1 | M102: =IF(OR(H102="",F102="",G102=""),"",H102-G102-F102-H102*$B$3+IF(L102="",0,L102)) -> 63.223 | N102: =IF(OR(M102="",H102=0,H102=""),"",M102/H102) -> 0.23195143 | O102: =IF(N102="","",IF(N102<0,"PREJUÍZO",IF(N102<0.1,"CRÍTICO (<10%)",IF(N102<0.15,"ABAIXO DA META (10-15%)",IF(N102<=0.2,"DENTRO DA META (15-20%)","ACIMA DA META (>20%)"))))) -> ACIMA DA META (>20%)
A103: L2460-AML | B103: Medios | C103: Rio Grande do Sul Capital | D103: 290.17 | E103: 0 | F103: 140.97 | G103: 39.01 | H103: =IF(D103="","",D103*(1-E103)) -> 290.17 | I103: =IF(OR(G103="",H103=""),"",G103/H103) -> 0.13443843 | J103: =IF(OR(B103="",C103=""),"",INDEX(Ref_Frete!$B$2:$G$54,MATCH(C103,Ref_Frete!$A$2:$A$54,0),IF(B103="Pequenos",2,IF(B103="Medios",4,6)))) -> 59.9 | K103: =IF(OR(B103="",C103=""),"",INDEX(Ref_Frete!$B$2:$G$54,MATCH(C103,Ref_Frete!$A$2:$A$54,0),IF(B103="Pequenos",1,IF(B103="Medios",3,5)))) -> 89 | L103: =IF(OR(J103="",K103=""),"",J103-K103) -> -29.1 | M103: =IF(OR(H103="",F103="",G103=""),"",H103-G103-F103-H103*$B$3+IF(L103="",0,L103)) -> 52.073 | N103: =IF(OR(M103="",H103=0,H103=""),"",M103/H103) -> 0.17945687 | O103: =IF(N103="","",IF(N103<0,"PREJUÍZO",IF(N103<0.1,"CRÍTICO (<10%)",IF(N103<0.15,"ABAIXO DA META (10-15%)",IF(N103<=0.2,"DENTRO DA META (15-20%)","ACIMA DA META (>20%)"))))) -> DENTRO DA META (15-20%)
A104: L2460-AML | B104: Medios | C104: São Paulo Interior | D104: 290.17 | E104: 0 | F104: 140.97 | G104: 39.01 | H104: =IF(D104="","",D104*(1-E104)) -> 290.17 | I104: =IF(OR(G104="",H104=""),"",G104/H104) -> 0.13443843 | J104: =IF(OR(B104="",C104=""),"",INDEX(Ref_Frete!$B$2:$G$54,MATCH(C104,Ref_Frete!$A$2:$A$54,0),IF(B104="Pequenos",2,IF(B104="Medios",4,6)))) -> 39.9 | K104: =IF(OR(B104="",C104=""),"",INDEX(Ref_Frete!$B$2:$G$54,MATCH(C104,Ref_Frete!$A$2:$A$54,0),IF(B104="Pequenos",1,IF(B104="Medios",3,5)))) -> 49 | L104: =IF(OR(J104="",K104=""),"",J104-K104) -> -9.1 | M104: =IF(OR(H104="",F104="",G104=""),"",H104-G104-F104-H104*$B$3+IF(L104="",0,L104)) -> 72.073 | N104: =IF(OR(M104="",H104=0,H104=""),"",M104/H104) -> 0.24838198 | O104: =IF(N104="","",IF(N104<0,"PREJUÍZO",IF(N104<0.1,"CRÍTICO (<10%)",IF(N104<0.15,"ABAIXO DA META (10-15%)",IF(N104<=0.2,"DENTRO DA META (15-20%)","ACIMA DA META (>20%)"))))) -> ACIMA DA META (>20%)
A105: L2460-B | B105: Medios | C105: Rio Grande do Sul Capital | D105: 299.31 | E105: 0 | F105: 152.83 | G105: 40.11 | H105: =IF(D105="","",D105*(1-E105)) -> 299.31 | I105: =IF(OR(G105="",H105=""),"",G105/H105) -> 0.13400822 | J105: =IF(OR(B105="",C105=""),"",INDEX(Ref_Frete!$B$2:$G$54,MATCH(C105,Ref_Frete!$A$2:$A$54,0),IF(B105="Pequenos",2,IF(B105="Medios",4,6)))) -> 59.9 | K105: =IF(OR(B105="",C105=""),"",INDEX(Ref_Frete!$B$2:$G$54,MATCH(C105,Ref_Frete!$A$2:$A$54,0),IF(B105="Pequenos",1,IF(B105="Medios",3,5)))) -> 89 | L105: =IF(OR(J105="",K105=""),"",J105-K105) -> -29.1 | M105: =IF(OR(H105="",F105="",G105=""),"",H105-G105-F105-H105*$B$3+IF(L105="",0,L105)) -> 47.339 | N105: =IF(OR(M105="",H105=0,H105=""),"",M105/H105) -> 0.15816044 | O105: =IF(N105="","",IF(N105<0,"PREJUÍZO",IF(N105<0.1,"CRÍTICO (<10%)",IF(N105<0.15,"ABAIXO DA META (10-15%)",IF(N105<=0.2,"DENTRO DA META (15-20%)","ACIMA DA META (>20%)"))))) -> DENTRO DA META (15-20%)
A106: L2460-B | B106: Medios | C106: São Paulo Interior | D106: 299.31 | E106: 0 | F106: 152.83 | G106: 40.11 | H106: =IF(D106="","",D106*(1-E106)) -> 299.31 | I106: =IF(OR(G106="",H106=""),"",G106/H106) -> 0.13400822 | J106: =IF(OR(B106="",C106=""),"",INDEX(Ref_Frete!$B$2:$G$54,MATCH(C106,Ref_Frete!$A$2:$A$54,0),IF(B106="Pequenos",2,IF(B106="Medios",4,6)))) -> 39.9 | K106: =IF(OR(B106="",C106=""),"",INDEX(Ref_Frete!$B$2:$G$54,MATCH(C106,Ref_Frete!$A$2:$A$54,0),IF(B106="Pequenos",1,IF(B106="Medios",3,5)))) -> 49 | L106: =IF(OR(J106="",K106=""),"",J106-K106) -> -9.1 | M106: =IF(OR(H106="",F106="",G106=""),"",H106-G106-F106-H106*$B$3+IF(L106="",0,L106)) -> 67.339 | N106: =IF(OR(M106="",H106=0,H106=""),"",M106/H106) -> 0.22498079 | O106: =IF(N106="","",IF(N106<0,"PREJUÍZO",IF(N106<0.1,"CRÍTICO (<10%)",IF(N106<0.15,"ABAIXO DA META (10-15%)",IF(N106<=0.2,"DENTRO DA META (15-20%)","ACIMA DA META (>20%)"))))) -> ACIMA DA META (>20%)
A107: L2460-CP | B107: Medios | C107: Rio Grande do Sul Capital | D107: 335.68 | E107: 0 | F107: 172.67 | G107: 44.47 | H107: =IF(D107="","",D107*(1-E107)) -> 335.68 | I107: =IF(OR(G107="",H107=""),"",G107/H107) -> 0.13247736 | J107: =IF(OR(B107="",C107=""),"",INDEX(Ref_Frete!$B$2:$G$54,MATCH(C107,Ref_Frete!$A$2:$A$54,0),IF(B107="Pequenos",2,IF(B107="Medios",4,6)))) -> 59.9 | K107: =IF(OR(B107="",C107=""),"",INDEX(Ref_Frete!$B$2:$G$54,MATCH(C107,Ref_Frete!$A$2:$A$54,0),IF(B107="Pequenos",1,IF(B107="Medios",3,5)))) -> 89 | L107: =IF(OR(J107="",K107=""),"",J107-K107) -> -29.1 | M107: =IF(OR(H107="",F107="",G107=""),"",H107-G107-F107-H107*$B$3+IF(L107="",0,L107)) -> 55.872 | N107: =IF(OR(M107="",H107=0,H107=""),"",M107/H107) -> 0.16644423 | O107: =IF(N107="","",IF(N107<0,"PREJUÍZO",IF(N107<0.1,"CRÍTICO (<10%)",IF(N107<0.15,"ABAIXO DA META (10-15%)",IF(N107<=0.2,"DENTRO DA META (15-20%)","ACIMA DA META (>20%)"))))) -> DENTRO DA META (15-20%)
A108: L2460-CP | B108: Medios | C108: São Paulo Interior | D108: 335.68 | E108: 0 | F108: 172.67 | G108: 44.47 | H108: =IF(D108="","",D108*(1-E108)) -> 335.68 | I108: =IF(OR(G108="",H108=""),"",G108/H108) -> 0.13247736 | J108: =IF(OR(B108="",C108=""),"",INDEX(Ref_Frete!$B$2:$G$54,MATCH(C108,Ref_Frete!$A$2:$A$54,0),IF(B108="Pequenos",2,IF(B108="Medios",4,6)))) -> 39.9 | K108: =IF(OR(B108="",C108=""),"",INDEX(Ref_Frete!$B$2:$G$54,MATCH(C108,Ref_Frete!$A$2:$A$54,0),IF(B108="Pequenos",1,IF(B108="Medios",3,5)))) -> 49 | L108: =IF(OR(J108="",K108=""),"",J108-K108) -> -9.1 | M108: =IF(OR(H108="",F108="",G108=""),"",H108-G108-F108-H108*$B$3+IF(L108="",0,L108)) -> 75.872 | N108: =IF(OR(M108="",H108=0,H108=""),"",M108/H108) -> 0.22602479 | O108: =IF(N108="","",IF(N108<0,"PREJUÍZO",IF(N108<0.1,"CRÍTICO (<10%)",IF(N108<0.15,"ABAIXO DA META (10-15%)",IF(N108<=0.2,"DENTRO DA META (15-20%)","ACIMA DA META (>20%)"))))) -> ACIMA DA META (>20%)
A109: L2460-CZ | B109: Medios | C109: Rio Grande do Sul Capital | D109: 318.56 | E109: 0 | F109: 159 | G109: 42.42 | H109: =IF(D109="","",D109*(1-E109)) -> 318.56 | I109: =IF(OR(G109="",H109=""),"",G109/H109) -> 0.13316173 | J109: =IF(OR(B109="",C109=""),"",INDEX(Ref_Frete!$B$2:$G$54,MATCH(C109,Ref_Frete!$A$2:$A$54,0),IF(B109="Pequenos",2,IF(B109="Medios",4,6)))) -> 59.9 | K109: =IF(OR(B109="",C109=""),"",INDEX(Ref_Frete!$B$2:$G$54,MATCH(C109,Ref_Frete!$A$2:$A$54,0),IF(B109="Pequenos",1,IF(B109="Medios",3,5)))) -> 89 | L109: =IF(OR(J109="",K109=""),"",J109-K109) -> -29.1 | M109: =IF(OR(H109="",F109="",G109=""),"",H109-G109-F109-H109*$B$3+IF(L109="",0,L109)) -> 56.184 | N109: =IF(OR(M109="",H109=0,H109=""),"",M109/H109) -> 0.17636866 | O109: =IF(N109="","",IF(N109<0,"PREJUÍZO",IF(N109<0.1,"CRÍTICO (<10%)",IF(N109<0.15,"ABAIXO DA META (10-15%)",IF(N109<=0.2,"DENTRO DA META (15-20%)","ACIMA DA META (>20%)"))))) -> DENTRO DA META (15-20%)
A110: L2460-CZ | B110: Medios | C110: São Paulo Interior | D110: 318.56 | E110: 0 | F110: 159 | G110: 42.42 | H110: =IF(D110="","",D110*(1-E110)) -> 318.56 | I110: =IF(OR(G110="",H110=""),"",G110/H110) -> 0.13316173 | J110: =IF(OR(B110="",C110=""),"",INDEX(Ref_Frete!$B$2:$G$54,MATCH(C110,Ref_Frete!$A$2:$A$54,0),IF(B110="Pequenos",2,IF(B110="Medios",4,6)))) -> 39.9 | K110: =IF(OR(B110="",C110=""),"",INDEX(Ref_Frete!$B$2:$G$54,MATCH(C110,Ref_Frete!$A$2:$A$54,0),IF(B110="Pequenos",1,IF(B110="Medios",3,5)))) -> 49 | L110: =IF(OR(J110="",K110=""),"",J110-K110) -> -9.1 | M110: =IF(OR(H110="",F110="",G110=""),"",H110-G110-F110-H110*$B$3+IF(L110="",0,L110)) -> 76.184 | N110: =IF(OR(M110="",H110=0,H110=""),"",M110/H110) -> 0.23915118 | O110: =IF(N110="","",IF(N110<0,"PREJUÍZO",IF(N110<0.1,"CRÍTICO (<10%)",IF(N110<0.15,"ABAIXO DA META (10-15%)",IF(N110<=0.2,"DENTRO DA META (15-20%)","ACIMA DA META (>20%)"))))) -> ACIMA DA META (>20%)
... A180: PG4050 | B180: Medios | C180: São Paulo Interior | D180: 460.12 | E180: 0 | F180: 228.9 | G180: 59.4 | H180: =IF(D180="","",D180*(1-E180)) -> 460.12 | I180: =IF(OR(G180="",H180=""),"",G180/H180) -> 0.12909676 | J180: =IF(OR(B180="",C180=""),"",INDEX(Ref_Frete!$B$2:$G$54,MATCH(C180,Ref_Frete!$A$2:$A$54,0),IF(B180="Pequenos",2,IF(B180="Medios",4,6)))) -> 39.9 | K180: =IF(OR(B180="",C180=""),"",INDEX(Ref_Frete!$B$2:$G$54,MATCH(C180,Ref_Frete!$A$2:$A$54,0),IF(B180="Pequenos",1,IF(B180="Medios",3,5)))) -> 49 | L180: =IF(OR(J180="",K180=""),"",J180-K180) -> -9.1 | M180: =IF(OR(H180="",F180="",G180=""),"",H180-G180-F180-H180*$B$3+IF(L180="",0,L180)) -> 116.708 | N180: =IF(OR(M180="",H180=0,H180=""),"",M180/H180) -> 0.25364687 | O180: =IF(N180="","",IF(N180<0,"PREJUÍZO",IF(N180<0.1,"CRÍTICO (<10%)",IF(N180<0.15,"ABAIXO DA META (10-15%)",IF(N180<=0.2,"DENTRO DA META (15-20%)","ACIMA DA META (>20%)"))))) -> ACIMA DA META (>20%)
...

Sheet Registro_Vendas
A1: REGISTRO DE VENDAS — lucro real venda a venda
A2: Preencha as colunas AZUIS. PEDIDO COM VÁRIOS SKUs: uma linha por SKU (mesma data e nº de pedido), frete cobrado e frete real SÓ NA 1ª LINHA — nas demais digite 0 por cima. Tarifa: estimada; sobrescreva com a real do extrato.
A3: Imposto (%): | B3: 0.1 | C3: Tarifa padrão (%): | D3: 0.135
A5: Data | B5: SKU | C5: Qtd | D5: Região destino | E5: Preço unit. (R$) | F5: Desconto/promo total (R$) | G5: Receita produtos (R$) | H5: Classe | I5: Frete cobrado do cliente (R$) | J5: Frete real pago (R$) | K5: Tarifa Amazon (R$) | L5: Custo produtos (R$) | M5: Imposto (R$) | N5: LUCRO (R$) | O5: Margem | P5: Veredito | Q5: Nº do Pedido / Obs | R5: Origem
A6: 46228 | B6: L2030-B | C6: 1 | D6: Distrito Federal | E6: =IF($B6="","",INDEX(Simulador!$D$7:$D$232,MATCH($B6,Simulador!$A$7:$A$232,0))) -> 153.72 | G6: =IF(OR($B6="",$C6=""),"",$C6*E6-IF(F6="",0,F6)) -> 153.72 | H6: =IF($B6="","",INDEX(Simulador!$B$7:$B$232,MATCH($B6,Simulador!$A$7:$A$232,0))) -> Pequenos | I6: =IF(OR(H6="",$D6=""),"",INDEX(Ref_Frete!$B$2:$G$54,MATCH($D6,Ref_Frete!$A$2:$A$54,0),IF(H6="Pequenos",2,IF(H6="Medios",4,6)))) -> 52 | J6: 19.73 | K6: 27.78 | L6: =IF(OR($B6="",$C6=""),"",$C6*INDEX(Simulador!$F$7:$F$232,MATCH($B6,Simulador!$A$7:$A$232,0))) -> 75.68 | M6: =IF(G6="","",G6*$B$3) -> 15.372 | N6: =IF(OR(G6="",J6=""),"",G6+IF(I6="",0,I6)-J6-K6-L6-M6) -> 67.158 | O6: =IF(OR(N6="",G6=0,G6=""),"",N6/G6) -> 0.43688525 | P6: =IF(O6="","",IF(O6<0,"PREJUÍZO",IF(O6<0.1,"CRÍTICO (<10%)",IF(O6<0.15,"ABAIXO DA META (10-15%)",IF(O6<=0.2,"DENTRO DA META (15-20%)","ACIMA DA META (>20%)"))))) -> ACIMA DA META (>20%) | R6: Orgânico
A7: 46236 | B7: L3070-B | C7: 1 | D7: Minas Gerais Interior | E7: =IF($B7="","",INDEX(Simulador!$D$7:$D$232,MATCH($B7,Simulador!$A$7:$A$232,0))) -> 543.85 | G7: =IF(OR($B7="",$C7=""),"",$C7*E7-IF(F7="",0,F7)) -> 543.85 | H7: =IF($B7="","",INDEX(Simulador!$B$7:$B$232,MATCH($B7,Simulador!$A$7:$A$232,0))) -> Medios | I7: =IF(OR(H7="",$D7=""),"",INDEX(Ref_Frete!$B$2:$G$54,MATCH($D7,Ref_Frete!$A$2:$A$54,0),IF(H7="Pequenos",2,IF(H7="Medios",4,6)))) -> 69.9 | J7: 80.69 | K7: =IF(G7="","",ROUND($D$3*(G7+IF(I7="",0,I7)),2)) -> 82.86 | L7: =IF(OR($B7="",$C7=""),"",$C7*INDEX(Simulador!$F$7:$F$232,MATCH($B7,Simulador!$A$7:$A$232,0))) -> 279.42 | M7: =IF(G7="","",G7*$B$3) -> 54.385 | N7: =IF(OR(G7="",J7=""),"",G7+IF(I7="",0,I7)-J7-K7-L7-M7) -> 116.395 | O7: =IF(OR(N7="",G7=0,G7=""),"",N7/G7) -> 0.21402041 | P7: =IF(O7="","",IF(O7<0,"PREJUÍZO",IF(O7<0.1,"CRÍTICO (<10%)",IF(O7<0.15,"ABAIXO DA META (10-15%)",IF(O7<=0.2,"DENTRO DA META (15-20%)","ACIMA DA META (>20%)"))))) -> ACIMA DA META (>20%) | Q7: Geral DBA | R7: Ads
A8: 46234 | B8: L2430-B | C8: 2 | D8: São Paulo Capital | E8: =IF($B8="","",INDEX(Simulador!$D$7:$D$232,MATCH($B8,Simulador!$A$7:$A$232,0))) -> 198.03 | G8: =IF(OR($B8="",$C8=""),"",$C8*E8-IF(F8="",0,F8)) -> 396.06 | H8: =IF($B8="","",INDEX(Simulador!$B$7:$B$232,MATCH($B8,Simulador!$A$7:$A$232,0))) -> Pequenos | I8: =IF(OR(H8="",$D8=""),"",INDEX(Ref_Frete!$B$2:$G$54,MATCH($D8,Ref_Frete!$A$2:$A$54,0),IF(H8="Pequenos",2,IF(H8="Medios",4,6)))) -> 12.9 | J8: 28.29 | K8: =IF(G8="","",ROUND($D$3*(G8+IF(I8="",0,I8)),2)) -> 55.21 | L8: =IF(OR($B8="",$C8=""),"",$C8*INDEX(Simulador!$F$7:$F$232,MATCH($B8,Simulador!$A$7:$A$232,0))) -> 206.84 | M8: =IF(G8="","",G8*$B$3) -> 39.606 | N8: =IF(OR(G8="",J8=""),"",G8+IF(I8="",0,I8)-J8-K8-L8-M8) -> 79.014 | O8: =IF(OR(N8="",G8=0,G8=""),"",N8/G8) -> 0.19950008 | P8: =IF(O8="","",IF(O8<0,"PREJUÍZO",IF(O8<0.1,"CRÍTICO (<10%)",IF(O8<0.15,"ABAIXO DA META (10-15%)",IF(O8<=0.2,"DENTRO DA META (15-20%)","ACIMA DA META (>20%)"))))) -> DENTRO DA META (15-20%) | Q8: Relatório Ads registra como L2425-B — conferir SKU | R8: Ads
A9: 46233 | B9: EGC | C9: 1 | D9: Rio Grande do Sul Capital | E9: =IF($B9="","",INDEX(Simulador!$D$7:$D$232,MATCH($B9,Simulador!$A$7:$A$232,0))) -> 674.62 | G9: =IF(OR($B9="",$C9=""),"",$C9*E9-IF(F9="",0,F9)) -> 674.62 | H9: =IF($B9="","",INDEX(Simulador!$B$7:$B$232,MATCH($B9,Simulador!$A$7:$A$232,0))) -> Medios | I9: =IF(OR(H9="",$D9=""),"",INDEX(Ref_Frete!$B$2:$G$54,MATCH($D9,Ref_Frete!$A$2:$A$54,0),IF(H9="Pequenos",2,IF(H9="Medios",4,6)))) -> 59.9 | J9: 53.59 | K9: =IF(G9="","",ROUND($D$3*(G9+IF(I9="",0,I9)),2)) -> 99.16 | L9: =IF(OR($B9="",$C9=""),"",$C9*INDEX(Simulador!$F$7:$F$232,MATCH($B9,Simulador!$A$7:$A$232,0))) -> 365.7 | M9: =IF(G9="","",G9*$B$3) -> 67.462 | N9: =IF(OR(G9="",J9=""),"",G9+IF(I9="",0,I9)-J9-K9-L9-M9) -> 148.608 | O9: =IF(OR(N9="",G9=0,G9=""),"",N9/G9) -> 0.22028401 | P9: =IF(O9="","",IF(O9<0,"PREJUÍZO",IF(O9<0.1,"CRÍTICO (<10%)",IF(O9<0.15,"ABAIXO DA META (10-15%)",IF(O9<=0.2,"DENTRO DA META (15-20%)","ACIMA DA META (>20%)"))))) -> ACIMA DA META (>20%) | R9: Orgânico
A10: 46186 | B10: L1618-A | C10: 1 | D10: Paraná Capital | E10: 96.63 | G10: =IF(OR($B10="",$C10=""),"",$C10*E10-IF(F10="",0,F10)) -> 96.63 | H10: =IF($B10="","",INDEX(Simulador!$B$7:$B$232,MATCH($B10,Simulador!$A$7:$A$232,0))) -> Pequenos | I10: 23.51 | J10: 15.65 | K10: 14.42 | L10: =IF(OR($B10="",$C10=""),"",$C10*INDEX(Simulador!$F$7:$F$232,MATCH($B10,Simulador!$A$7:$A$232,0))) -> 48.18 | M10: =IF(G10="","",G10*$B$3) -> 9.663 | N10: =IF(OR(G10="",J10=""),"",G10+IF(I10="",0,I10)-J10-K10-L10-M10) -> 32.227 | O10: =IF(OR(N10="",G10=0,G10=""),"",N10/G10) -> 0.33350926 | P10: =IF(O10="","",IF(O10<0,"PREJUÍZO",IF(O10<0.1,"CRÍTICO (<10%)",IF(O10<0.15,"ABAIXO DA META (10-15%)",IF(O10<=0.2,"DENTRO DA META (15-20%)","ACIMA DA META (>20%)"))))) -> ACIMA DA META (>20%) | Q10: Preço da época (pré-reajuste; atual 104,90). | R10: Orgânico
A11: 46192 | B11: L2460-CP | C11: 1 | D11: Rio de Janeiro Capital | E11: =IF($B11="","",INDEX(Simulador!$D$7:$D$232,MATCH($B11,Simulador!$A$7:$A$232,0))) -> 335.68 | G11: =IF(OR($B11="",$C11=""),"",$C11*E11-IF(F11="",0,F11)) -> 335.68 | H11: =IF($B11="","",INDEX(Simulador!$B$7:$B$232,MATCH($B11,Simulador!$A$7:$A$232,0))) -> Medios | I11: 51 | J11: 35.52 | K11: =IF(G11="","",ROUND($D$3*(G11+IF(I11="",0,I11)),2)) -> 52.2 | L11: =IF(OR($B11="",$C11=""),"",$C11*INDEX(Simulador!$F$7:$F$232,MATCH($B11,Simulador!$A$7:$A$232,0))) -> 172.67 | M11: =IF(G11="","",G11*$B$3) -> 33.568 | N11: =IF(OR(G11="",J11=""),"",G11+IF(I11="",0,I11)-J11-K11-L11-M11) -> 92.722 | O11: =IF(OR(N11="",G11=0,G11=""),"",N11/G11) -> 0.2762214 | P11: =IF(O11="","",IF(O11<0,"PREJUÍZO",IF(O11<0.1,"CRÍTICO (<10%)",IF(O11<0.15,"ABAIXO DA META (10-15%)",IF(O11<=0.2,"DENTRO DA META (15-20%)","ACIMA DA META (>20%)"))))) -> ACIMA DA META (>20%) | Q11: auto - termo "coletor de pilhas" | R11: Ads
A12: 46195 | B12: Q3060-B | C12: 1 | D12: Rio de Janeiro Capital | E12: =IF($B12="","",INDEX(Simulador!$D$7:$D$232,MATCH($B12,Simulador!$A$7:$A$232,0))) -> 532.93 | G12: =IF(OR($B12="",$C12=""),"",$C12*E12-IF(F12="",0,F12)) -> 532.93 | H12: =IF($B12="","",INDEX(Simulador!$B$7:$B$232,MATCH($B12,Simulador!$A$7:$A$232,0))) -> Medios | I12: 59.99 | J12: 42.41 | K12: =IF(G12="","",ROUND($D$3*(G12+IF(I12="",0,I12)),2)) -> 80.04 | L12: =IF(OR($B12="",$C12=""),"",$C12*INDEX(Simulador!$F$7:$F$232,MATCH($B12,Simulador!$A$7:$A$232,0))) -> 301.03 | M12: =IF(G12="","",G12*$B$3) -> 53.293 | N12: =IF(OR(G12="",J12=""),"",G12+IF(I12="",0,I12)-J12-K12-L12-M12) -> 116.147 | O12: =IF(OR(N12="",G12=0,G12=""),"",N12/G12) -> 0.21794044 | P12: =IF(O12="","",IF(O12<0,"PREJUÍZO",IF(O12<0.1,"CRÍTICO (<10%)",IF(O12<0.15,"ABAIXO DA META (10-15%)",IF(O12<=0.2,"DENTRO DA META (15-20%)","ACIMA DA META (>20%)"))))) -> ACIMA DA META (>20%) | R12: Orgânico
A13: 46195 | B13: P3070 | C13: 1 | D13: São Paulo Capital | E13: =IF($B13="","",INDEX(Simulador!$D$7:$D$232,MATCH($B13,Simulador!$A$7:$A$232,0))) -> 616.18 | G13: =IF(OR($B13="",$C13=""),"",$C13*E13-IF(F13="",0,F13)) -> 616.18 | H13: =IF($B13="","",INDEX(Simulador!$B$7:$B$232,MATCH($B13,Simulador!$A$7:$A$232,0))) -> Medios | I13: 40.01 | J13: 37.22 | K13: =IF(G13="","",ROUND($D$3*(G13+IF(I13="",0,I13)),2)) -> 88.59 | L13: =IF(OR($B13="",$C13=""),"",$C13*INDEX(Simulador!$F$7:$F$232,MATCH($B13,Simulador!$A$7:$A$232,0))) -> 307.26 | M13: =IF(G13="","",G13*$B$3) -> 61.618 | N13: =IF(OR(G13="",J13=""),"",G13+IF(I13="",0,I13)-J13-K13-L13-M13) -> 161.502 | O13: =IF(OR(N13="",G13=0,G13=""),"",N13/G13) -> 0.26210198 | P13: =IF(O13="","",IF(O13<0,"PREJUÍZO",IF(O13<0.1,"CRÍTICO (<10%)",IF(O13<0.15,"ABAIXO DA META (10-15%)",IF(O13<=0.2,"DENTRO DA META (15-20%)","ACIMA DA META (>20%)"))))) -> ACIMA DA META (>20%) | Q13: PI - ASIN B0G9B9RCMF | R13: Ads
A14: 46197 | B14: L2450-AML | C14: 1 | D14: São Paulo Interior | E14: 203.16 | G14: =IF(OR($B14="",$C14=""),"",$C14*E14-IF(F14="",0,F14)) -> 203.16 | H14: =IF($B14="","",INDEX(Simulador!$B$7:$B$232,MATCH($B14,Simulador!$A$7:$A$232,0))) -> Pequenos | I14: 16.25 | J14: 34.5 | K14: =IF(G14="","",ROUND($D$3*(G14+IF(I14="",0,I14)),2)) -> 29.62 | L14: =IF(OR($B14="",$C14=""),"",$C14*INDEX(Simulador!$F$7:$F$232,MATCH($B14,Simulador!$A$7:$A$232,0))) -> 139.49 | M14: =IF(G14="","",G14*$B$3) -> 20.316 | N14: =IF(OR(G14="",J14=""),"",G14+IF(I14="",0,I14)-J14-K14-L14-M14) -> -4.516 | O14: =IF(OR(N14="",G14=0,G14=""),"",N14/G14) -> -0.022228785 | P14: =IF(O14="","",IF(O14<0,"PREJUÍZO",IF(O14<0.1,"CRÍTICO (<10%)",IF(O14<0.15,"ABAIXO DA META (10-15%)",IF(O14<=0.2,"DENTRO DA META (15-20%)","ACIMA DA META (>20%)"))))) -> PREJUÍZO | Q14: Preço da época (pré-reajuste; atual 259,90). Relatório Ads registra como L2025 — conferir SKU | R14: Ads
A15: 46198 | B15: PG2460 | C15: 1 | D15: Paraná Capital | E15: =IF($B15="","",INDEX(Simulador!$D$7:$D$232,MATCH($B15,Simulador!$A$7:$A$232,0))) -> 248.75 | G15: =IF(OR($B15="",$C15=""),"",$C15*E15-IF(F15="",0,F15)) -> 248.75 | H15: =IF($B15="","",INDEX(Simulador!$B$7:$B$232,MATCH($B15,Simulador!$A$7:$A$232,0))) -> Medios | I15: 46.01 | J15: 37.97 | K15: =IF(G15="","",ROUND($D$3*(G15+IF(I15="",0,I15)),2)) -> 39.79 | L15: =IF(OR($B15="",$C15=""),"",$C15*INDEX(Simulador!$F$7:$F$232,MATCH($B15,Simulador!$A$7:$A$232,0))) -> 124.42 | M15: =IF(G15="","",G15*$B$3) -> 24.875 | N15: =IF(OR(G15="",J15=""),"",G15+IF(I15="",0,I15)-J15-K15-L15-M15) -> 67.705 | O15: =IF(OR(N15="",G15=0,G15=""),"",N15/G15) -> 0.2721809 | P15: =IF(O15="","",IF(O15<0,"PREJUÍZO",IF(O15<0.1,"CRÍTICO (<10%)",IF(O15<0.15,"ABAIXO DA META (10-15%)",IF(O15<=0.2,"DENTRO DA META (15-20%)","ACIMA DA META (>20%)"))))) -> ACIMA DA META (>20%) | Q15: auto - "suporte para guarda chuva" | R15: Ads
A16: 46199 | B16: PXP | C16: 2 | D16: São Paulo Capital | E16: =IF($B16="","",INDEX(Simulador!$D$7:$D$232,MATCH($B16,Simulador!$A$7:$A$232,0))) -> 167.89 | G16: =IF(OR($B16="",$C16=""),"",$C16*E16-IF(F16="",0,F16)) -> 335.78 | H16: =IF($B16="","",INDEX(Simulador!$B$7:$B$232,MATCH($B16,Simulador!$A$7:$A$232,0))) -> Pequenos | I16: =IF(OR(H16="",$D16=""),"",INDEX(Ref_Frete!$B$2:$G$54,MATCH($D16,Ref_Frete!$A$2:$A$54,0),IF(H16="Pequenos",2,IF(H16="Medios",4,6)))) -> 12.9 | J16: 15.49 | K16: =IF(G16="","",ROUND($D$3*(G16+IF(I16="",0,I16)),2)) -> 47.07 | L16: =IF(OR($B16="",$C16=""),"",$C16*INDEX(Simulador!$F$7:$F$232,MATCH($B16,Simulador!$A$7:$A$232,0))) -> 169.58 | M16: =IF(G16="","",G16*$B$3) -> 33.578 | N16: =IF(OR(G16="",J16=""),"",G16+IF(I16="",0,I16)-J16-K16-L16-M16) -> 82.962 | O16: =IF(OR(N16="",G16=0,G16=""),"",N16/G16) -> 0.24707249 | P16: =IF(O16="","",IF(O16<0,"PREJUÍZO",IF(O16<0.1,"CRÍTICO (<10%)",IF(O16<0.15,"ABAIXO DA META (10-15%)",IF(O16<=0.2,"DENTRO DA META (15-20%)","ACIMA DA META (>20%)"))))) -> ACIMA DA META (>20%) | Q16: Órfã 26/06 identificada: 2× PXP (335,78) | R16: Orgânico
A17: 46202 | B17: SP-01 | C17: 1 | D17: Rio Grande do Norte Capital | E17: =IF($B17="","",INDEX(Simulador!$D$7:$D$232,MATCH($B17,Simulador!$A$7:$A$232,0))) -> 475.31 | G17: =IF(OR($B17="",$C17=""),"",$C17*E17-IF(F17="",0,F17)) -> 475.31 | H17: =IF($B17="","",INDEX(Simulador!$B$7:$B$232,MATCH($B17,Simulador!$A$7:$A$232,0))) -> Medios | I17: 163 | J17: 81.96 | K17: =IF(G17="","",ROUND($D$3*(G17+IF(I17="",0,I17)),2)) -> 86.17 | L17: =IF(OR($B17="",$C17=""),"",$C17*INDEX(Simulador!$F$7:$F$232,MATCH($B17,Simulador!$A$7:$A$232,0))) -> 247.86 | M17: =IF(G17="","",G17*$B$3) -> 47.531 | N17: =IF(OR(G17="",J17=""),"",G17+IF(I17="",0,I17)-J17-K17-L17-M17) -> 174.789 | O17: =IF(OR(N17="",G17=0,G17=""),"",N17/G17) -> 0.36773685 | P17: =IF(O17="","",IF(O17<0,"PREJUÍZO",IF(O17<0.1,"CRÍTICO (<10%)",IF(O17<0.15,"ABAIXO DA META (10-15%)",IF(O17<=0.2,"DENTRO DA META (15-20%)","ACIMA DA META (>20%)"))))) -> ACIMA DA META (>20%) | Q17: PI - ASIN B0C5JTQBXF | R17: Ads
A18: 46202 | B18: P3050 | C18: 1 | D18: Distrito Federal | E18: =IF($B18="","",INDEX(Simulador!$D$7:$D$232,MATCH($B18,Simulador!$A$7:$A$232,0))) -> 467.67 | F18: 37.41 | G18: =IF(OR($B18="",$C18=""),"",$C18*E18-IF(F18="",0,F18)) -> 430.26 | H18: =IF($B18="","",INDEX(Simulador!$B$7:$B$232,MATCH($B18,Simulador!$A$7:$A$232,0))) -> Medios | I18: =IF(OR(H18="",$D18=""),"",INDEX(Ref_Frete!$B$2:$G$54,MATCH($D18,Ref_Frete!$A$2:$A$54,0),IF(H18="Pequenos",2,IF(H18="Medios",4,6)))) -> 122 | J18: 53.08 | K18: =IF(G18="","",ROUND($D$3*(G18+IF(I18="",0,I18)),2)) -> 74.56 | L18: =IF(OR($B18="",$C18=""),"",$C18*INDEX(Simulador!$F$7:$F$232,MATCH($B18,Simulador!$A$7:$A$232,0))) -> 240.55 | M18: =IF(G18="","",G18*$B$3) -> 43.026 | N18: =IF(OR(G18="",J18=""),"",G18+IF(I18="",0,I18)-J18-K18-L18-M18) -> 141.044 | O18: =IF(OR(N18="",G18=0,G18=""),"",N18/G18) -> 0.32781109 | P18: =IF(O18="","",IF(O18<0,"PREJUÍZO",IF(O18<0.1,"CRÍTICO (<10%)",IF(O18<0.15,"ABAIXO DA META (10-15%)",IF(O18<=0.2,"DENTRO DA META (15-20%)","ACIMA DA META (>20%)"))))) -> ACIMA DA META (>20%) | Q18: PI - ASIN B0CYWMQ93Y | R18: Ads
A19: 46205 | B19: EGC | C19: 1 | D19: São Paulo Capital | E19: =IF($B19="","",INDEX(Simulador!$D$7:$D$232,MATCH($B19,Simulador!$A$7:$A$232,0))) -> 674.62 | G19: =IF(OR($B19="",$C19=""),"",$C19*E19-IF(F19="",0,F19)) -> 674.62 | H19: =IF($B19="","",INDEX(Simulador!$B$7:$B$232,MATCH($B19,Simulador!$A$7:$A$232,0))) -> Medios | I19: =IF(OR(H19="",$D19=""),"",INDEX(Ref_Frete!$B$2:$G$54,MATCH($D19,Ref_Frete!$A$2:$A$54,0),IF(H19="Pequenos",2,IF(H19="Medios",4,6)))) -> 34.9 | J19: 44.98 | K19: =IF(G19="","",ROUND($D$3*(G19+IF(I19="",0,I19)),2)) -> 95.79 | L19: =IF(OR($B19="",$C19=""),"",$C19*INDEX(Simulador!$F$7:$F$232,MATCH($B19,Simulador!$A$7:$A$232,0))) -> 365.7 | M19: =IF(G19="","",G19*$B$3) -> 67.462 | N19: =IF(OR(G19="",J19=""),"",G19+IF(I19="",0,I19)-J19-K19-L19-M19) -> 135.588 | O19: =IF(OR(N19="",G19=0,G19=""),"",N19/G19) -> 0.20098426 | P19: =IF(O19="","",IF(O19<0,"PREJUÍZO",IF(O19<0.1,"CRÍTICO (<10%)",IF(O19<0.15,"ABAIXO DA META (10-15%)",IF(O19<=0.2,"DENTRO DA META (15-20%)","ACIMA DA META (>20%)"))))) -> ACIMA DA META (>20%) | Q19: painel indica pedido em 01/07 | R19: Orgânico
A20: 46205 | B20: PXP | C20: 1 | D20: Goiás Capital | E20: 167.89 | G20: =IF(OR($B20="",$C20=""),"",$C20*E20-IF(F20="",0,F20)) -> 167.89 | H20: =IF($B20="","",INDEX(Simulador!$B$7:$B$232,MATCH($B20,Simulador!$A$7:$A$232,0))) -> Pequenos | I20: 59.49 | J20: 27.29 | K20: =IF(G20="","",ROUND($D$3*(G20+IF(I20="",0,I20)),2)) -> 30.7 | L20: =IF(OR($B20="",$C20=""),"",$C20*INDEX(Simulador!$F$7:$F$232,MATCH($B20,Simulador!$A$7:$A$232,0))) -> 84.79 | M20: =IF(G20="","",G20*$B$3) -> 16.789 | N20: =IF(OR(G20="",J20=""),"",G20+IF(I20="",0,I20)-J20-K20-L20-M20) -> 67.811 | O20: =IF(OR(N20="",G20=0,G20=""),"",N20/G20) -> 0.40390136 | P20: =IF(O20="","",IF(O20<0,"PREJUÍZO",IF(O20<0.1,"CRÍTICO (<10%)",IF(O20<0.15,"ABAIXO DA META (10-15%)",IF(O20<=0.2,"DENTRO DA META (15-20%)","ACIMA DA META (>20%)"))))) -> ACIMA DA META (>20%) | Q20: Pedido conjunto Goiânia (PXP+PXM 02/07) — frete do pedido NESTA linha | R20: Ads
A21: 46205 | B21: PXM | C21: 1 | D21: Goiás Capital | E21: 203.54 | G21: =IF(OR($B21="",$C21=""),"",$C21*E21-IF(F21="",0,F21)) -> 203.54 | H21: =IF($B21="","",INDEX(Simulador!$B$7:$B$232,MATCH($B21,Simulador!$A$7:$A$232,0))) -> Pequenos | I21: 0 | J21: 0 | K21: =IF(G21="","",ROUND($D$3*(G21+IF(I21="",0,I21)),2)) -> 27.48 | L21: =IF(OR($B21="",$C21=""),"",$C21*INDEX(Simulador!$F$7:$F$232,MATCH($B21,Simulador!$A$7:$A$232,0))) -> 102.8 | M21: =IF(G21="","",G21*$B$3) -> 20.354 | N21: =IF(OR(G21="",J21=""),"",G21+IF(I21="",0,I21)-J21-K21-L21-M21) -> 52.906 | O21: =IF(OR(N21="",G21=0,G21=""),"",N21/G21) -> 0.25992925 | P21: =IF(O21="","",IF(O21<0,"PREJUÍZO",IF(O21<0.1,"CRÍTICO (<10%)",IF(O21<0.15,"ABAIXO DA META (10-15%)",IF(O21<=0.2,"DENTRO DA META (15-20%)","ACIMA DA META (>20%)"))))) -> ACIMA DA META (>20%) | Q21: Mesmo pedido da linha 20 — frete zerado aqui | R21: Ads
A22: 46206 | B22: L2450--CZ | C22: 1 | D22: Bahia Capital | E22: =IF($B22="","",INDEX(Simulador!$D$7:$D$232,MATCH($B22,Simulador!$A$7:$A$232,0))) -> 319.58 | G22: =IF(OR($B22="",$C22=""),"",$C22*E22-IF(F22="",0,F22)) -> 319.58 | H22: =IF($B22="","",INDEX(Simulador!$B$7:$B$232,MATCH($B22,Simulador!$A$7:$A$232,0))) -> Pequenos | I22: 82.01 | J22: 24.6 | K22: =IF(G22="","",ROUND($D$3*(G22+IF(I22="",0,I22)),2)) -> 54.21 | L22: =IF(OR($B22="",$C22=""),"",$C22*INDEX(Simulador!$F$7:$F$232,MATCH($B22,Simulador!$A$7:$A$232,0))) -> 156 | M22: =IF(G22="","",G22*$B$3) -> 31.958 | N22: =IF(OR(G22="",J22=""),"",G22+IF(I22="",0,I22)-J22-K22-L22-M22) -> 134.822 | O22: =IF(OR(N22="",G22=0,G22=""),"",N22/G22) -> 0.42187246 | P22: =IF(O22="","",IF(O22<0,"PREJUÍZO",IF(O22<0.1,"CRÍTICO (<10%)",IF(O22<0.15,"ABAIXO DA META (10-15%)",IF(O22<=0.2,"DENTRO DA META (15-20%)","ACIMA DA META (>20%)"))))) -> ACIMA DA META (>20%) | Q22: Código do catálogo é L2450--CZ (hífen duplo). Preencher região e frete real | R22: Orgânico
A23: 46207 | B23: PXM | C23: 1 | D23: São Paulo Capital | E23: =IF($B23="","",INDEX(Simulador!$D$7:$D$232,MATCH($B23,Simulador!$A$7:$A$232,0))) -> 203.54 | G23: =IF(OR($B23="",$C23=""),"",$C23*E23-IF(F23="",0,F23)) -> 203.54 | H23: =IF($B23="","",INDEX(Simulador!$B$7:$B$232,MATCH($B23,Simulador!$A$7:$A$232,0))) -> Pequenos | I23: =IF(OR(H23="",$D23=""),"",INDEX(Ref_Frete!$B$2:$G$54,MATCH($D23,Ref_Frete!$A$2:$A$54,0),IF(H23="Pequenos",2,IF(H23="Medios",4,6)))) -> 12.9 | J23: 15.49 | K23: =IF(G23="","",ROUND($D$3*(G23+IF(I23="",0,I23)),2)) -> 29.22 | L23: =IF(OR($B23="",$C23=""),"",$C23*INDEX(Simulador!$F$7:$F$232,MATCH($B23,Simulador!$A$7:$A$232,0))) -> 102.8 | M23: =IF(G23="","",G23*$B$3) -> 20.354 | N23: =IF(OR(G23="",J23=""),"",G23+IF(I23="",0,I23)-J23-K23-L23-M23) -> 48.576 | O23: =IF(OR(N23="",G23=0,G23=""),"",N23/G23) -> 0.23865579 | P23: =IF(O23="","",IF(O23<0,"PREJUÍZO",IF(O23<0.1,"CRÍTICO (<10%)",IF(O23<0.15,"ABAIXO DA META (10-15%)",IF(O23<=0.2,"DENTRO DA META (15-20%)","ACIMA DA META (>20%)"))))) -> ACIMA DA META (>20%) | Q23: Preencher região e frete real | R23: Orgânico
A24: 46211 | B24: PXM | C24: 3 | D24: Ceará Capital | E24: =IF($B24="","",INDEX(Simulador!$D$7:$D$232,MATCH($B24,Simulador!$A$7:$A$232,0))) -> 203.54 | G24: =IF(OR($B24="",$C24=""),"",$C24*E24-IF(F24="",0,F24)) -> 610.62 | H24: =IF($B24="","",INDEX(Simulador!$B$7:$B$232,MATCH($B24,Simulador!$A$7:$A$232,0))) -> Pequenos | I24: 159.96 | J24: 80.55 | K24: =IF(G24="","",ROUND($D$3*(G24+IF(I24="",0,I24)),2)) -> 104.03 | L24: =IF(OR($B24="",$C24=""),"",$C24*INDEX(Simulador!$F$7:$F$232,MATCH($B24,Simulador!$A$7:$A$232,0))) -> 308.4 | M24: =IF(G24="","",G24*$B$3) -> 61.062 | N24: =IF(OR(G24="",J24=""),"",G24+IF(I24="",0,I24)-J24-K24-L24-M24) -> 216.538 | O24: =IF(OR(N24="",G24=0,G24=""),"",N24/G24) -> 0.35461989 | P24: =IF(O24="","",IF(O24<0,"PREJUÍZO",IF(O24<0.1,"CRÍTICO (<10%)",IF(O24<0.15,"ABAIXO DA META (10-15%)",IF(O24<=0.2,"DENTRO DA META (15-20%)","ACIMA DA META (>20%)"))))) -> ACIMA DA META (>20%) | Q24: auto — "suporte p/ extintor de 6 kg" · região/frete a preencher | R24: Ads
A25: 46212 | B25: L1618-T | C25: 1 | D25: São Paulo Interior | E25: =IF($B25="","",INDEX(Simulador!$D$7:$D$232,MATCH($B25,Simulador!$A$7:$A$232,0))) -> 116 | G25: =IF(OR($B25="",$C25=""),"",$C25*E25-IF(F25="",0,F25)) -> 116 | H25: =IF($B25="","",INDEX(Simulador!$B$7:$B$232,MATCH($B25,Simulador!$A$7:$A$232,0))) -> Pequenos | I25: =IF(OR(H25="",$D25=""),"",INDEX(Ref_Frete!$B$2:$G$54,MATCH($D25,Ref_Frete!$A$2:$A$54,0),IF(H25="Pequenos",2,IF(H25="Medios",4,6)))) -> 16.9 | J25: 16.64 | K25: =IF(G25="","",ROUND($D$3*(G25+IF(I25="",0,I25)),2)) -> 17.94 | L25: =IF(OR($B25="",$C25=""),"",$C25*INDEX(Simulador!$F$7:$F$232,MATCH($B25,Simulador!$A$7:$A$232,0))) -> 54.47 | M25: =IF(G25="","",G25*$B$3) -> 11.6 | N25: =IF(OR(G25="",J25=""),"",G25+IF(I25="",0,I25)-J25-K25-L25-M25) -> 32.25 | O25: =IF(OR(N25="",G25=0,G25=""),"",N25/G25) -> 0.27801724 | P25: =IF(O25="","",IF(O25<0,"PREJUÍZO",IF(O25<0.1,"CRÍTICO (<10%)",IF(O25<0.15,"ABAIXO DA META (10-15%)",IF(O25<=0.2,"DENTRO DA META (15-20%)","ACIMA DA META (>20%)"))))) -> ACIMA DA META (>20%) | Q25: Venda do termo "lixeira pia" (ACOS 48% — caso da O1) | R25: Ads
A26: 46212 | B26: P3050 | C26: 1 | D26: Minas Gerais Interior | E26: =IF($B26="","",INDEX(Simulador!$D$7:$D$232,MATCH($B26,Simulador!$A$7:$A$232,0))) -> 467.67 | G26: =IF(OR($B26="",$C26=""),"",$C26*E26-IF(F26="",0,F26)) -> 467.67 | H26: =IF($B26="","",INDEX(Simulador!$B$7:$B$232,MATCH($B26,Simulador!$A$7:$A$232,0))) -> Medios | I26: =IF(OR(H26="",$D26=""),"",INDEX(Ref_Frete!$B$2:$G$54,MATCH($D26,Ref_Frete!$A$2:$A$54,0),IF(H26="Pequenos",2,IF(H26="Medios",4,6)))) -> 69.9 | J26: 57.77 | K26: =IF(G26="","",ROUND($D$3*(G26+IF(I26="",0,I26)),2)) -> 72.57 | L26: =IF(OR($B26="",$C26=""),"",$C26*INDEX(Simulador!$F$7:$F$232,MATCH($B26,Simulador!$A$7:$A$232,0))) -> 240.55 | M26: =IF(G26="","",G26*$B$3) -> 46.767 | N26: =IF(OR(G26="",J26=""),"",G26+IF(I26="",0,I26)-J26-K26-L26-M26) -> 119.913 | O26: =IF(OR(N26="",G26=0,G26=""),"",N26/G26) -> 0.25640516 | P26: =IF(O26="","",IF(O26<0,"PREJUÍZO",IF(O26<0.1,"CRÍTICO (<10%)",IF(O26<0.15,"ABAIXO DA META (10-15%)",IF(O26<=0.2,"DENTRO DA META (15-20%)","ACIMA DA META (>20%)"))))) -> ACIMA DA META (>20%) | Q26: 2ª venda do P3050 via Ads | R26: Ads
A27: 46223 | B27: PXM | C27: 1 | D27: Goiás Capital | E27: =IF($B27="","",INDEX(Simulador!$D$7:$D$232,MATCH($B27,Simulador!$A$7:$A$232,0))) -> 203.54 | F27: 10.18 | G27: =IF(OR($B27="",$C27=""),"",$C27*E27-IF(F27="",0,F27)) -> 193.36 | H27: =IF($B27="","",INDEX(Simulador!$B$7:$B$232,MATCH($B27,Simulador!$A$7:$A$232,0))) -> Pequenos | I27: 37.49 | J27: 20.94 | K27: =IF(G27="","",ROUND($D$3*(G27+IF(I27="",0,I27)),2)) -> 31.16 | L27: =IF(OR($B27="",$C27=""),"",$C27*INDEX(Simulador!$F$7:$F$232,MATCH($B27,Simulador!$A$7:$A$232,0))) -> 102.8 | M27: =IF(G27="","",G27*$B$3) -> 19.336 | N27: =IF(OR(G27="",J27=""),"",G27+IF(I27="",0,I27)-J27-K27-L27-M27) -> 56.614 | O27: =IF(OR(N27="",G27=0,G27=""),"",N27/G27) -> 0.29279065 | P27: =IF(O27="","",IF(O27<0,"PREJUÍZO",IF(O27<0.1,"CRÍTICO (<10%)",IF(O27<0.15,"ABAIXO DA META (10-15%)",IF(O27<=0.2,"DENTRO DA META (15-20%)","ACIMA DA META (>20%)"))))) -> ACIMA DA META (>20%) | Q27: PI PXM · região/frete a preencher | R27: Ads
