Workbook

Sheet Legenda
A1: LEGENDA — Precificação por Marketplace · Winnet Metais · v1.0 (09/10/2026)
A3: COMO A PLANILHA FUNCIONA
A4: Parâmetros | B4: Imposto, ADS, margem mínima e custo fixo por marketplace (bloco 1) e comissão por categoria × marketplace (bloco 2). Toda taxa vive aqui — nenhuma está escondida em fórmula.
A5: Produtos | B5: Base única: código, nome, categoria e custo (Vl. Revenda 6%). As seis abas de marketplace e o Comparativo leem desta aba pela mesma linha.
A6: ML Clássico / ML Premium / Amazon / Via (Casas Bahia) / MadeiraMadeira / Magalu | B6: Uma aba por canal, mesma estrutura da Precificação ML original. Nelas você preenche só Frete, Comissão manual (opcional), Preço Manual, % Desc. Promo, Atualizado em e Observação.
A7: Comparativo | B7: Preço usado e margem de cada produto em todos os canais, lado a lado, com menor/maior margem. Somente leitura.
A8: CORES
A9: Texto AZUL | B9: Entrada manual (custo, frete, comissão manual, preço manual, % promo, taxas).
A10: Fundo AMARELO | B10: Entrada que mais pesa no resultado (custo, frete, taxas).
A11: Texto VERDE | B11: Vem de outra aba (Produtos ou Parâmetros). Não edite — edite na origem.
A12: Fundo DOURADO (✅ usado) | B12: Valor que alimenta os cálculos: o manual se preenchido, senão o automático (vale para comissão e para preço).
A13: VERMELHO | B13: Lucro ou margem negativos — prejuízo. Também sinaliza '⚠ categoria' (produto sem categoria válida) e 'INVALIDO' (taxas somadas ≥ 100%).
A14: LARANJA | B14: Margem abaixo da margem mínima do canal (aba Parâmetros).
A15: COLUNAS DAS ABAS DE MARKETPLACE
A16: Código / Produto / Categoria / Custo (A–D) | B16: Lidos de Produtos. A Categoria escolhe a comissão na aba Parâmetros.
A17: Frete (E) | B17: Só se aplica ao Mercado Livre: custo de envio que fica com a Winnet, por produto. Amazon, Via, MadeiraMadeira e Magalu ficam com 0 por decisão do LEO (09/10/2026).
A18: Comissão categoria (F) | B18: Procurada em Parâmetros pela categoria do produto e pelo canal da aba.
A19: ✏ Comissão manual (G) | B19: Opcional. Digite como fração (0,12 = 12%) quando o anúncio tiver comissão diferente da categoria. Nas abas ML já traz as taxas que estavam embutidas linha a linha na planilha original.
A20: ✅ Comissão usada (H) | B20: G se preenchida, senão F.
A21: ⚙ Preço Sugerido (I) | B21: Preço = (Custo + Frete + Custo fixo) ÷ (1 − Comissão usada − Imposto − ADS − Margem mínima). Mesma lógica da Precificação ML, agora com as taxas vindas de Parâmetros.
A22: ✏ Preço Manual (J) | B22: Digite o preço praticado no canal. Vazio ou 0 = usa o sugerido.
A23: ✅ Preço Usado (K) | B23: J se preenchido, senão I. Base de tudo.
A24: Comissão / Imposto / ADS / Custo fixo (L–O) | B24: Valores em R$ sobre o Preço Usado (custo fixo é por unidade).
A25: Lucro Líq (P) / Margem (Q) | B25: Preço Usado − Custo − Frete − L − M − N − O, e a margem sobre o Preço Usado.
A26: % Desc. Promo (R) e colunas S–X | B26: Digite o desconto como fração (0,10 = 10%). S–X recalculam tudo para o preço promocional.
A27: Atualizado em (Y) / Observação (Z) | B27: Controle livre. Nas abas ML, Y recebeu a data que estava anexada ao nome do produto na planilha original (ex.: '09/10').
A28: FONTES E PREMISSAS DESTA VERSÃO
A29: Produtos e custos | B29: Precificacao_ML_Winnet_Metais_.xlsx (LEO, 09/10/2026): 294 produtos, nomes limpos do sufixo de data. Custos conferidos contra a Planilha Mestra v4.3.5: 108 SKUs em comum, nenhuma divergência. EMB-03P e EMB-05P vieram só da Mestra.
A30: ML Clássico e ML Premium | B30: Frete, Preço Manual e comissão por linha copiados das abas originais; Preço Usado, Lucro e Margem idênticos aos da origem em todas as linhas. Diferença proposital: o Preço Sugerido agora usa a comissão da própria linha (a original usava sempre 13%/18% no divisor, mesmo nas linhas com 12%, 10,5%, 15% etc.). Preço Manual = 0 na origem foi tratado como vazio (usa o sugerido).
A31: Amazon | B31: Preço Manual = 'Preço de venda' do Simulador da Mestra v4.3.5, cenário São Paulo Interior (Livro set/26 fechado em 05/10). Frete = 0 por decisão do LEO (09/10/2026). Grafias Amazon: L2450--CZ, SP-PP, SP-FF (coluna F de Produtos). Para decisão Amazon, a Mestra continua sendo a fonte oficial.
A32: Comissões | B32: Tabela enviada pelo LEO em 09/10/2026 (print). Onde havia faixa, usado o limite superior (conservador); a faixa está anotada em Parâmetros. ML Clássico 13% e Premium 18% vieram do título da planilha original. Amazon 13% em todas as categorias por decisão do LEO (09/10/2026).
A33: Taxas ainda não confirmadas | B33: ADS e custo fixo por unidade de Via, MadeiraMadeira e Magalu (e ADS da Amazon) estão com os valores da planilha ML (3% e R$ 0). Amazon está em 13% por decisão do LEO (09/10/2026), em linha com a tarifa efetiva média da Mestra (13,0%, que incide sobre preço + frete cobrado); aqui ela incide só sobre o preço.
A34: Categoria 'Acessórios (aros e tampas)' | B34: Não consta no print. Recebeu as mesmas comissões de 'Lixeiras em inox' como premissa — confirmar.
A35: COMO INCLUIR PRODUTO
A36: Passo único | B36: Em Produtos, preencha a próxima linha vazia (código, nome, categoria, custo). As abas de canal e o Comparativo já têm fórmulas até a linha 349; depois disso, copie a última linha de fórmulas para baixo.

Sheet Parâmetros
A1: PARÂMETROS — taxas por marketplace e comissão por categoria
A2: Células AZUIS em fundo amarelo são entradas. Tudo o que está nas abas dos marketplaces lê daqui.
A3: Marketplace | B3: Imposto (%) | C3: ADS (%) | D3: Margem mín. (%) | E3: Custo fixo por unidade (R$) | F3: Observação
A4: ML Clássico | B4: 0.1 | C4: 0.03 | D4: 0.2 | E4: 0 | F4: Imposto, ADS e margem herdados da Precificação ML (LEO, 09/10/2026).
A5: ML Premium | B5: 0.1 | C5: 0.03 | D5: 0.2 | E5: 0 | F5: Idem Clássico.
A6: Amazon | B6: 0.1 | C6: 0.03 | D6: 0.2 | E6: 0 | F6: ADS 3% é o valor da planilha ML — confirmar o % real de Amazon Ads sobre a venda.
A7: Via (Casas Bahia) | B7: 0.1 | C7: 0.03 | D7: 0.2 | E7: 0 | F7: ADS e custo fixo não confirmados para este canal.
A8: MadeiraMadeira | B8: 0.1 | C8: 0.03 | D8: 0.2 | E8: 0 | F8: ADS e custo fixo não confirmados para este canal.
A9: Magalu | B9: 0.1 | C9: 0.03 | D9: 0.2 | E9: 0 | F9: ADS e custo fixo não confirmados para este canal.
A11: COMISSÃO POR CATEGORIA × MARKETPLACE (fonte: tabela enviada pelo LEO em 09/10/2026 · faixas → usado o limite superior · confirmar no painel de cada canal · uma linha pode sobrepor com 'Comissão manual' na aba do canal)
A12: Categoria | B12: ML Clássico | C12: ML Premium | D12: Amazon | E12: Via (Casas Bahia) | F12: MadeiraMadeira | G12: Magalu | H12: Faixa informada / observação
A13: Bituqueiras e cinzeiros | B13: 0.13 | C13: 0.18 | D13: 0.13 | E13: 0.21 | F13: 0.19 | G13: 0.18
A14: Lixeiras em inox | B14: 0.13 | C14: 0.18 | D14: 0.13 | E14: 0.21 | F14: 0.19 | G14: 0.18
A15: Lixeiras com pedal | B15: 0.13 | C15: 0.18 | D15: 0.13 | E15: 0.21 | F15: 0.19 | G15: 0.18
A16: Lixeiras de coleta seletiva | B16: 0.13 | C16: 0.18 | D16: 0.13 | E16: 0.21 | F16: 0.19 | G16: 0.18 | H16: Via 20%–21%
A17: Porta-extintores | B17: 0.13 | C17: 0.18 | D17: 0.13 | E17: 0.21 | F17: 0.19 | G17: 0.18 | H17: MadeiraMadeira 15%–19% · Amazon 11%–12% no print, 13% por decisão do LEO · Via 20%–21%
A18: Porta-guarda-chuvas | B18: 0.13 | C18: 0.18 | D18: 0.13 | E18: 0.21 | F18: 0.19 | G18: 0.199 | H18: Magalu 18%–19,9%
A19: Coletores de pilhas | B19: 0.13 | C19: 0.18 | D19: 0.13 | E19: 0.21 | F19: 0.19 | G19: 0.18 | H19: Via 20%–21%
A20: Placas de piso molhado | B20: 0.13 | C20: 0.18 | D20: 0.13 | E20: 0.21 | F20: 0.19 | G20: 0.18 | H20: MadeiraMadeira 15%–19% · Amazon 11%–12% no print, 13% por decisão do LEO · Via 20%–21%
A21: Ensacadores | B21: 0.13 | C21: 0.18 | D21: 0.13 | E21: 0.21 | F21: 0.19 | G21: 0.18 | H21: MadeiraMadeira 15%–19% · Amazon 11%–12% no print, 13% por decisão do LEO · Via 20%–21% (no print: 'Ensacadores de lixeira'; no catálogo é o Ensacador de guarda-chuvas EGC/REGC)
A22: Acessórios (aros e tampas) | B22: 0.13 | C22: 0.18 | D22: 0.13 | E22: 0.21 | F22: 0.19 | G22: 0.18 | H22: PREMISSA: não consta no print — copiado de 'Lixeiras em inox'. Confirmar.

Sheet Produtos
A1: PRODUTOS — base única de código, nome, categoria e custo (as abas dos marketplaces leem daqui)
A2: Entradas em AZUL. Para incluir produto: use a próxima linha vazia (as abas já têm fórmulas até a linha 349). Categoria define a comissão (aba Parâmetros).
A3: Código | B3: Produto | C3: Categoria (comissão) | D3: Vl. Revenda 6% = Custo (R$) | E3: Vl. Nota (R$) opcional | F3: SKU na Amazon (se diferente) | G3: Observação
A4: L1618 | B4: Lixeira Aço Inox s/Tampa 16x18 03L | C4: Lixeiras em inox | D4: 39.8
A5: L1623 | B5: Lixeira Aço Inox s/Tampa 16x23 05L | C5: Lixeiras em inox | D5: 49.15
A6: L2025 | B6: Lixeira Aço Inox s/Tampa 20x25 07L | C6: Lixeiras em inox | D6: 51.82
A7: L2030 | B7: Lixeira Aço Inox s/Tampa 20x30 10L | C7: Lixeiras em inox | D7: 55.49
A8: L2425 | B8: Lixeira Aço Inox s/Tampa 24x25 13L | C8: Lixeiras em inox | D8: 62.2
A9: L2430 | B9: Lixeira Aço Inox s/Tampa 24x30 15L | C9: Lixeiras em inox | D9: 69.93
A10: L2440 | B10: Lixeira Aço Inox s/Tampa 24x40 20L | C10: Lixeiras em inox | D10: 85.92
A11: L2450 | B11: Lixeira Aço Inox s/Tampa 24x50 25L | C11: Lixeiras em inox | D11: 116.34
A12: L2460 | B12: Lixeira Aço Inox s/Tampa 24x60 27L | C12: Lixeiras em inox | D12: 117.84
A13: L2470 | B13: Lixeira Aço Inox s/Tampa 24x70 30L | C13: Lixeiras em inox | D13: 186.46
A14: L3040 | B14: Lixeira Aço Inox s/Tampa 30x40 30L | C14: Lixeiras em inox | D14: 116.77
A15: L3050 | B15: Lixeira Aço Inox s/Tampa 30x50 35L | C15: Lixeiras em inox | D15: 159.84
... A174: EMB-08 | B174: Lixeira Embutir Pia 8L c/Balde Alumínio | C174: Lixeiras em inox | D174: 181.23
A175: EMB-03P | B175: Lixeira Embutir Pia 3L c/Balde Alumínio e Tampa Preta | C175: Lixeiras em inox | D175: 127.42 | G175: Só na Amazon — custo da Mestra v4.3.5
A176: EMB-05P | B176: Lixeira Embutir Pia 5L c/Balde Alumínio e Tampa Preta | C176: Lixeiras em inox | D176: 154.46 | G176: Só na Amazon — custo da Mestra v4.3.5
A177: Q2430-A | B177: Lixeira Quadrada c/Aro 24x30 15L | C177: Lixeiras em inox | D177: 121.07
A178: Q2460-A | B178: Lixeira Quadrada c/Aro 24x60 30L | C178: Lixeiras em inox | D178: 183.04
A179: Q3060-A | B179: Lixeira Quadrada c/Aro 30x60 50L | C179: Lixeiras em inox | D179: 277.75
A180: Q4070-A | B180: Lixeira Quadrada c/Aro 40x70 100L | C180: Lixeiras em inox | D180: 580.13
A181: Q2430-B | B181: Lixeira Quadrada c/Aro Basculante 24x30 15L | C181: Lixeiras em inox | D181: 149.88
A182: Q2460-B | B182: Lixeira Quadrada c/Aro Basculante 24x60 30L | C182: Lixeiras em inox | D182: 198.38
A183: Q3060-B | B183: Lixeira Quadrada c/Aro Basculante 30x60 50L | C183: Lixeiras em inox | D183: 301.03
A184: Q4070-B | B184: Lixeira Quadrada c/Aro Basculante 40x70 100L | C184: Lixeiras em inox | D184: 619.95
A185: PQ-2430 | B185: Lixeira quadrada com Tampa Pedal de Aço inox 24x30 15L | C185: Lixeiras com pedal | D185: 220.94
A186: PQ-2460 | B186: Lixeira quadrada com Tampa Pedal de Aço inox 24x60 30L | C186: Lixeiras com pedal | D186: 303.74
A187: PQ-3060 | B187: Lixeira quadrada com Tampa Pedal de Aço inox 30x60 50L | C187: Lixeiras com pedal | D187: 408.87
A188: PQ-4070 | B188: Lixeira quadrada com Tampa Pedal de Aço inox 40x70 100L | C188: Lixeiras com pedal | D188: 905.26
... A208: L2030-T | B208: Lixeira de Aço inox 20x30 10L com tampa | C208: Lixeiras em inox | D208: 69.27
A209: A24 | B209: Aro 24cm Aço Inox | C209: Acessórios (aros e tampas) | D209: 38.11 | G209: Categoria assumida — confirmar
A210: A30 | B210: Aro 30cm Aço Inox | C210: Acessórios (aros e tampas) | D210: 44.27 | G210: Categoria assumida — confirmar
A211: A40 | B211: Aro 40cm Aço Inox | C211: Acessórios (aros e tampas) | D211: 94.36 | G211: Categoria assumida — confirmar
A212: A24B | B212: Aro 24cm c/Basculante Aço Inox | C212: Acessórios (aros e tampas) | D212: 52.34 | G212: Categoria assumida — confirmar
A213: A30B | B213: Aro 30cm c/Basculante Aço Inox | C213: Acessórios (aros e tampas) | D213: 68.24 | G213: Categoria assumida — confirmar
A214: A40B | B214: Aro 40cm c/Basculante Aço Inox | C214: Acessórios (aros e tampas) | D214: 136.51 | G214: Categoria assumida — confirmar
A215: A24C | B215: Aro 24cm Pintado | C215: Acessórios (aros e tampas) | D215: 50.43 | G215: Categoria assumida — confirmar
A216: A30C | B216: Aro 30cm Pintado | C216: Acessórios (aros e tampas) | D216: 64.43 | G216: Categoria assumida — confirmar
A217: A40BP | B217: Aro 40cm Pintado | C217: Acessórios (aros e tampas) | D217: 118.62 | G217: Categoria assumida — confirmar
...

Sheet ML Clássico
A1: ="MERCADO LIVRE — CLÁSSICO | Comissão por categoria (aba Parâmetros) ou manual por linha | Imposto "&TEXT(Parâmetros!$B$4,"0%")&" | ADS "&TEXT(Parâmetros!$C$4,"0.0%")&" | Margem mín. "&TEXT(Parâmetros!$D$4,"0%")&" | Custo fixo/un. R$ "&TEXT(Parâmetros!$E$4,"0.00") -> MERCADO LIVRE — CLÁSSICO | Comissão por categoria (aba Parâmetros) ou manual por linha | Imposto 10% | ADS 3.0% | Margem mín. 20% | Custo fixo/un. R$ 0.00
A2: PRODUTO | D2: ENTRADAS | F2: COMISSÃO | I2: PREÇO SUGERIDO | J2: PREÇO MANUAL | K2: PREÇO USADO | L2: COMPOSIÇÃO DO PREÇO | R2: PROMOÇÃO | Y2: CONTROLE
A3: Código | B3: Produto | C3: Categoria | D3: Vl. Revenda 6% = Custo (R$) | E3: Frete (R$) | F3: Comissão categoria (%) | G3: ✏ Comissão manual (%) | H3: ✅ Comissão usada (%) | I3: ⚙ Preço Sugerido | J3: ✏ Preço Manual | K3: ✅ Preço Usado | L3: Comissão (R$) | M3: Imposto (R$) | N3: ADS (R$) | O3: Custo fixo (R$) | P3: Lucro Líq (R$) | Q3: Margem (%) | R3: % Desc. Promo | S3: Preço Promo (R$) | T3: Comissão Promo (R$) | U3: Imposto Promo (R$) | V3: ADS Promo (R$) | W3: Lucro Promo (R$) | X3: Margem Promo (%) | Y3: Atualizado em | Z3: Observação
A4: =IF(Produtos!$A4="","",Produtos!$A4) -> L1618 | B4: =IF(Produtos!$A4="","",Produtos!$B4) -> Lixeira Aço Inox s/Tampa 16x18 03L | C4: =IF(Produtos!$A4="","",Produtos!$C4) -> Lixeiras em inox | D4: =IF(Produtos!$A4="","",IF(Produtos!$D4="","",Produtos!$D4)) -> 39.8 | E4: 14.15 | F4: =IF($A4="","",IF($C4="","⚠ categoria",IFERROR(INDEX(Parâmetros!$B$13:$B$22,MATCH($C4,Parâmetros!$A$13:$A$22,0)),"⚠ categoria"))) -> 0.13 | H4: =IF($A4="","",IF(ISNUMBER($G4),$G4,IF(ISNUMBER($F4),$F4,""))) -> 0.13 | I4: =IF(OR($A4="",NOT(ISNUMBER($D4)),NOT(ISNUMBER($H4))),"",IF((1-$H4-Parâmetros!$B$4-Parâmetros!$C$4-Parâmetros!$D$4)<=0,"INVALIDO",($D4+IF(ISNUMBER($E4),$E4,0)+IF(ISNUMBER(Parâmetros!$E$4),Parâmetros!$E$4,0))/(1-$H4-Parâmetros!$B$4-Parâmetros!$C$4-Parâmetros!$D$4))) -> 99.907407 | J4: 80.4 | K4: =IF(OR($A4="",NOT(ISNUMBER($D4)),NOT(ISNUMBER($H4))),"",IF(AND(ISNUMBER($J4),$J4>0),$J4,IF(ISNUMBER($I4),$I4,""))) -> 80.4 | L4: =IF(ISNUMBER($K4),$K4*$H4,"") -> 10.452 | M4: =IF(ISNUMBER($K4),$K4*Parâmetros!$B$4,"") -> 8.04 | N4: =IF(ISNUMBER($K4),$K4*Parâmetros!$C$4,"") -> 2.412 | O4: =IF(ISNUMBER($K4),IF(ISNUMBER(Parâmetros!$E$4),Parâmetros!$E$4,0),"") -> 0 | P4: =IF(ISNUMBER($K4),$K4-$D4-IF(ISNUMBER($E4),$E4,0)-$L4-$M4-$N4-$O4,"") -> 5.546 | Q4: =IF(AND(ISNUMBER($K4),$K4>0),$P4/$K4,"") -> 0.0689801 | S4: =IF(OR(NOT(ISNUMBER($R4)),$R4=0,NOT(ISNUMBER($K4))),"",$K4*(1-$R4)) | T4: =IF(ISNUMBER($S4),$S4*$H4,"") | U4: =IF(ISNUMBER($S4),$S4*Parâmetros!$B$4,"") | V4: =IF(ISNUMBER($S4),$S4*Parâmetros!$C$4,"") | W4: =IF(ISNUMBER($S4),$S4-$D4-IF(ISNUMBER($E4),$E4,0)-$O4-$T4-$U4-$V4,"") | X4: =IF(AND(ISNUMBER($S4),$S4>0),$W4/$S4,"")
A5: =IF(Produtos!$A5="","",Produtos!$A5) -> L1623 | B5: =IF(Produtos!$A5="","",Produtos!$B5) -> Lixeira Aço Inox s/Tampa 16x23 05L | C5: =IF(Produtos!$A5="","",Produtos!$C5) -> Lixeiras em inox | D5: =IF(Produtos!$A5="","",IF(Produtos!$D5="","",Produtos!$D5)) -> 49.15 | E5: 14.15 | F5: =IF($A5="","",IF($C5="","⚠ categoria",IFERROR(INDEX(Parâmetros!$B$13:$B$22,MATCH($C5,Parâmetros!$A$13:$A$22,0)),"⚠ categoria"))) -> 0.13 | H5: =IF($A5="","",IF(ISNUMBER($G5),$G5,IF(ISNUMBER($F5),$F5,""))) -> 0.13 | I5: =IF(OR($A5="",NOT(ISNUMBER($D5)),NOT(ISNUMBER($H5))),"",IF((1-$H5-Parâmetros!$B$4-Parâmetros!$C$4-Parâmetros!$D$4)<=0,"INVALIDO",($D5+IF(ISNUMBER($E5),$E5,0)+IF(ISNUMBER(Parâmetros!$E$4),Parâmetros!$E$4,0))/(1-$H5-Parâmetros!$B$4-Parâmetros!$C$4-Parâmetros!$D$4))) -> 117.22222 | J5: 97.96 | K5: =IF(OR($A5="",NOT(ISNUMBER($D5)),NOT(ISNUMBER($H5))),"",IF(AND(ISNUMBER($J5),$J5>0),$J5,IF(ISNUMBER($I5),$I5,""))) -> 97.96 | L5: =IF(ISNUMBER($K5),$K5*$H5,"") -> 12.7348 | M5: =IF(ISNUMBER($K5),$K5*Parâmetros!$B$4,"") -> 9.796 | N5: =IF(ISNUMBER($K5),$K5*Parâmetros!$C$4,"") -> 2.9388 | O5: =IF(ISNUMBER($K5),IF(ISNUMBER(Parâmetros!$E$4),Parâmetros!$E$4,0),"") -> 0 | P5: =IF(ISNUMBER($K5),$K5-$D5-IF(ISNUMBER($E5),$E5,0)-$L5-$M5-$N5-$O5,"") -> 9.1904 | Q5: =IF(AND(ISNUMBER($K5),$K5>0),$P5/$K5,"") -> 0.093817885 | S5: =IF(OR(NOT(ISNUMBER($R5)),$R5=0,NOT(ISNUMBER($K5))),"",$K5*(1-$R5)) | T5: =IF(ISNUMBER($S5),$S5*$H5,"") | U5: =IF(ISNUMBER($S5),$S5*Parâmetros!$B$4,"") | V5: =IF(ISNUMBER($S5),$S5*Parâmetros!$C$4,"") | W5: =IF(ISNUMBER($S5),$S5-$D5-IF(ISNUMBER($E5),$E5,0)-$O5-$T5-$U5-$V5,"") | X5: =IF(AND(ISNUMBER($S5),$S5>0),$W5/$S5,"")
A6: =IF(Produtos!$A6="","",Produtos!$A6) -> L2025 | B6: =IF(Produtos!$A6="","",Produtos!$B6) -> Lixeira Aço Inox s/Tampa 20x25 07L | C6: =IF(Produtos!$A6="","",Produtos!$C6) -> Lixeiras em inox | D6: =IF(Produtos!$A6="","",IF(Produtos!$D6="","",Produtos!$D6)) -> 51.82 | E6: 16.85 | F6: =IF($A6="","",IF($C6="","⚠ categoria",IFERROR(INDEX(Parâmetros!$B$13:$B$22,MATCH($C6,Parâmetros!$A$13:$A$22,0)),"⚠ categoria"))) -> 0.13 | H6: =IF($A6="","",IF(ISNUMBER($G6),$G6,IF(ISNUMBER($F6),$F6,""))) -> 0.13 | I6: =IF(OR($A6="",NOT(ISNUMBER($D6)),NOT(ISNUMBER($H6))),"",IF((1-$H6-Parâmetros!$B$4-Parâmetros!$C$4-Parâmetros!$D$4)<=0,"INVALIDO",($D6+IF(ISNUMBER($E6),$E6,0)+IF(ISNUMBER(Parâmetros!$E$4),Parâmetros!$E$4,0))/(1-$H6-Parâmetros!$B$4-Parâmetros!$C$4-Parâmetros!$D$4))) -> 127.16667 | J6: 102.62 | K6: =IF(OR($A6="",NOT(ISNUMBER($D6)),NOT(ISNUMBER($H6))),"",IF(AND(ISNUMBER($J6),$J6>0),$J6,IF(ISNUMBER($I6),$I6,""))) -> 102.62 | L6: =IF(ISNUMBER($K6),$K6*$H6,"") -> 13.3406 | M6: =IF(ISNUMBER($K6),$K6*Parâmetros!$B$4,"") -> 10.262 | N6: =IF(ISNUMBER($K6),$K6*Parâmetros!$C$4,"") -> 3.0786 | O6: =IF(ISNUMBER($K6),IF(ISNUMBER(Parâmetros!$E$4),Parâmetros!$E$4,0),"") -> 0 | P6: =IF(ISNUMBER($K6),$K6-$D6-IF(ISNUMBER($E6),$E6,0)-$L6-$M6-$N6-$O6,"") -> 7.2688 | Q6: =IF(AND(ISNUMBER($K6),$K6>0),$P6/$K6,"") -> 0.070832196 | S6: =IF(OR(NOT(ISNUMBER($R6)),$R6=0,NOT(ISNUMBER($K6))),"",$K6*(1-$R6)) | T6: =IF(ISNUMBER($S6),$S6*$H6,"") | U6: =IF(ISNUMBER($S6),$S6*Parâmetros!$B$4,"") | V6: =IF(ISNUMBER($S6),$S6*Parâmetros!$C$4,"") | W6: =IF(ISNUMBER($S6),$S6-$D6-IF(ISNUMBER($E6),$E6,0)-$O6-$T6-$U6-$V6,"") | X6: =IF(AND(ISNUMBER($S6),$S6>0),$W6/$S6,"")
A7: =IF(Produtos!$A7="","",Produtos!$A7) -> L2030 | B7: =IF(Produtos!$A7="","",Produtos!$B7) -> Lixeira Aço Inox s/Tampa 20x30 10L | C7: =IF(Produtos!$A7="","",Produtos!$C7) -> Lixeiras em inox | D7: =IF(Produtos!$A7="","",IF(Produtos!$D7="","",Produtos!$D7)) -> 55.49 | E7: 16.85 | F7: =IF($A7="","",IF($C7="","⚠ categoria",IFERROR(INDEX(Parâmetros!$B$13:$B$22,MATCH($C7,Parâmetros!$A$13:$A$22,0)),"⚠ categoria"))) -> 0.13 | H7: =IF($A7="","",IF(ISNUMBER($G7),$G7,IF(ISNUMBER($F7),$F7,""))) -> 0.13 | I7: =IF(OR($A7="",NOT(ISNUMBER($D7)),NOT(ISNUMBER($H7))),"",IF((1-$H7-Parâmetros!$B$4-Parâmetros!$C$4-Parâmetros!$D$4)<=0,"INVALIDO",($D7+IF(ISNUMBER($E7),$E7,0)+IF(ISNUMBER(Parâmetros!$E$4),Parâmetros!$E$4,0))/(1-$H7-Parâmetros!$B$4-Parâmetros!$C$4-Parâmetros!$D$4))) -> 133.96296 | J7: 108.36 | K7: =IF(OR($A7="",NOT(ISNUMBER($D7)),NOT(ISNUMBER($H7))),"",IF(AND(ISNUMBER($J7),$J7>0),$J7,IF(ISNUMBER($I7),$I7,""))) -> 108.36 | L7: =IF(ISNUMBER($K7),$K7*$H7,"") -> 14.0868 | M7: =IF(ISNUMBER($K7),$K7*Parâmetros!$B$4,"") -> 10.836 | N7: =IF(ISNUMBER($K7),$K7*Parâmetros!$C$4,"") -> 3.2508 | O7: =IF(ISNUMBER($K7),IF(ISNUMBER(Parâmetros!$E$4),Parâmetros!$E$4,0),"") -> 0 | P7: =IF(ISNUMBER($K7),$K7-$D7-IF(ISNUMBER($E7),$E7,0)-$L7-$M7-$N7-$O7,"") -> 7.8464 | Q7: =IF(AND(ISNUMBER($K7),$K7>0),$P7/$K7,"") -> 0.072410484 | S7: =IF(OR(NOT(ISNUMBER($R7)),$R7=0,NOT(ISNUMBER($K7))),"",$K7*(1-$R7)) | T7: =IF(ISNUMBER($S7),$S7*$H7,"") | U7: =IF(ISNUMBER($S7),$S7*Parâmetros!$B$4,"") | V7: =IF(ISNUMBER($S7),$S7*Parâmetros!$C$4,"") | W7: =IF(ISNUMBER($S7),$S7-$D7-IF(ISNUMBER($E7),$E7,0)-$O7-$T7-$U7-$V7,"") | X7: =IF(AND(ISNUMBER($S7),$S7>0),$W7/$S7,"")
A8: =IF(Produtos!$A8="","",Produtos!$A8) -> L2425 | B8: =IF(Produtos!$A8="","",Produtos!$B8) -> Lixeira Aço Inox s/Tampa 24x25 13L | C8: =IF(Produtos!$A8="","",Produtos!$C8) -> Lixeiras em inox | D8: =IF(Produtos!$A8="","",IF(Produtos!$D8="","",Produtos!$D8)) -> 62.2 | F8: =IF($A8="","",IF($C8="","⚠ categoria",IFERROR(INDEX(Parâmetros!$B$13:$B$22,MATCH($C8,Parâmetros!$A$13:$A$22,0)),"⚠ categoria"))) -> 0.13 | H8: =IF($A8="","",IF(ISNUMBER($G8),$G8,IF(ISNUMBER($F8),$F8,""))) -> 0.13 | I8: =IF(OR($A8="",NOT(ISNUMBER($D8)),NOT(ISNUMBER($H8))),"",IF((1-$H8-Parâmetros!$B$4-Parâmetros!$C$4-Parâmetros!$D$4)<=0,"INVALIDO",($D8+IF(ISNUMBER($E8),$E8,0)+IF(ISNUMBER(Parâmetros!$E$4),Parâmetros!$E$4,0))/(1-$H8-Parâmetros!$B$4-Parâmetros!$C$4-Parâmetros!$D$4))) -> 115.18519 | K8: =IF(OR($A8="",NOT(ISNUMBER($D8)),NOT(ISNUMBER($H8))),"",IF(AND(ISNUMBER($J8),$J8>0),$J8,IF(ISNUMBER($I8),$I8,""))) -> 115.18519 | L8: =IF(ISNUMBER($K8),$K8*$H8,"") -> 14.974074 | M8: =IF(ISNUMBER($K8),$K8*Parâmetros!$B$4,"") -> 11.518519 | N8: =IF(ISNUMBER($K8),$K8*Parâmetros!$C$4,"") -> 3.4555556 | O8: =IF(ISNUMBER($K8),IF(ISNUMBER(Parâmetros!$E$4),Parâmetros!$E$4,0),"") -> 0 | P8: =IF(ISNUMBER($K8),$K8-$D8-IF(ISNUMBER($E8),$E8,0)-$L8-$M8-$N8-$O8,"") -> 23.037037 | Q8: =IF(AND(ISNUMBER($K8),$K8>0),$P8/$K8,"") -> 0.2 | S8: =IF(OR(NOT(ISNUMBER($R8)),$R8=0,NOT(ISNUMBER($K8))),"",$K8*(1-$R8)) | T8: =IF(ISNUMBER($S8),$S8*$H8,"") | U8: =IF(ISNUMBER($S8),$S8*Parâmetros!$B$4,"") | V8: =IF(ISNUMBER($S8),$S8*Parâmetros!$C$4,"") | W8: =IF(ISNUMBER($S8),$S8-$D8-IF(ISNUMBER($E8),$E8,0)-$O8-$T8-$U8-$V8,"") | X8: =IF(AND(ISNUMBER($S8),$S8>0),$W8/$S8,"")
A9: =IF(Produtos!$A9="","",Produtos!$A9) -> L2430 | B9: =IF(Produtos!$A9="","",Produtos!$B9) -> Lixeira Aço Inox s/Tampa 24x30 15L | C9: =IF(Produtos!$A9="","",Produtos!$C9) -> Lixeiras em inox | D9: =IF(Produtos!$A9="","",IF(Produtos!$D9="","",Produtos!$D9)) -> 69.93 | F9: =IF($A9="","",IF($C9="","⚠ categoria",IFERROR(INDEX(Parâmetros!$B$13:$B$22,MATCH($C9,Parâmetros!$A$13:$A$22,0)),"⚠ categoria"))) -> 0.13 | H9: =IF($A9="","",IF(ISNUMBER($G9),$G9,IF(ISNUMBER($F9),$F9,""))) -> 0.13 | I9: =IF(OR($A9="",NOT(ISNUMBER($D9)),NOT(ISNUMBER($H9))),"",IF((1-$H9-Parâmetros!$B$4-Parâmetros!$C$4-Parâmetros!$D$4)<=0,"INVALIDO",($D9+IF(ISNUMBER($E9),$E9,0)+IF(ISNUMBER(Parâmetros!$E$4),Parâmetros!$E$4,0))/(1-$H9-Parâmetros!$B$4-Parâmetros!$C$4-Parâmetros!$D$4))) -> 129.5 | K9: =IF(OR($A9="",NOT(ISNUMBER($D9)),NOT(ISNUMBER($H9))),"",IF(AND(ISNUMBER($J9),$J9>0),$J9,IF(ISNUMBER($I9),$I9,""))) -> 129.5 | L9: =IF(ISNUMBER($K9),$K9*$H9,"") -> 16.835 | M9: =IF(ISNUMBER($K9),$K9*Parâmetros!$B$4,"") -> 12.95 | N9: =IF(ISNUMBER($K9),$K9*Parâmetros!$C$4,"") -> 3.885 | O9: =IF(ISNUMBER($K9),IF(ISNUMBER(Parâmetros!$E$4),Parâmetros!$E$4,0),"") -> 0 | P9: =IF(ISNUMBER($K9),$K9-$D9-IF(ISNUMBER($E9),$E9,0)-$L9-$M9-$N9-$O9,"") -> 25.9 | Q9: =IF(AND(ISNUMBER($K9),$K9>0),$P9/$K9,"") -> 0.2 | S9: =IF(OR(NOT(ISNUMBER($R9)),$R9=0,NOT(ISNUMBER($K9))),"",$K9*(1-$R9)) | T9: =IF(ISNUMBER($S9),$S9*$H9,"") | U9: =IF(ISNUMBER($S9),$S9*Parâmetros!$B$4,"") | V9: =IF(ISNUMBER($S9),$S9*Parâmetros!$C$4,"") | W9: =IF(ISNUMBER($S9),$S9-$D9-IF(ISNUMBER($E9),$E9,0)-$O9-$T9-$U9-$V9,"") | X9: =IF(AND(ISNUMBER($S9),$S9>0),$W9/$S9,"")
A10: =IF(Produtos!$A10="","",Produtos!$A10) -> L2440 | B10: =IF(Produtos!$A10="","",Produtos!$B10) -> Lixeira Aço Inox s/Tampa 24x40 20L | C10: =IF(Produtos!$A10="","",Produtos!$C10) -> Lixeiras em inox | D10: =IF(Produtos!$A10="","",IF(Produtos!$D10="","",Produtos!$D10)) -> 85.92 | F10: =IF($A10="","",IF($C10="","⚠ categoria",IFERROR(INDEX(Parâmetros!$B$13:$B$22,MATCH($C10,Parâmetros!$A$13:$A$22,0)),"⚠ categoria"))) -> 0.13 | H10: =IF($A10="","",IF(ISNUMBER($G10),$G10,IF(ISNUMBER($F10),$F10,""))) -> 0.13 | I10: =IF(OR($A10="",NOT(ISNUMBER($D10)),NOT(ISNUMBER($H10))),"",IF((1-$H10-Parâmetros!$B$4-Parâmetros!$C$4-Parâmetros!$D$4)<=0,"INVALIDO",($D10+IF(ISNUMBER($E10),$E10,0)+IF(ISNUMBER(Parâmetros!$E$4),Parâmetros!$E$4,0))/(1-$H10-Parâmetros!$B$4-Parâmetros!$C$4-Parâmetros!$D$4))) -> 159.11111 | K10: =IF(OR($A10="",NOT(ISNUMBER($D10)),NOT(ISNUMBER($H10))),"",IF(AND(ISNUMBER($J10),$J10>0),$J10,IF(ISNUMBER($I10),$I10,""))) -> 159.11111 | L10: =IF(ISNUMBER($K10),$K10*$H10,"") -> 20.684444 | M10: =IF(ISNUMBER($K10),$K10*Parâmetros!$B$4,"") -> 15.911111 | N10: =IF(ISNUMBER($K10),$K10*Parâmetros!$C$4,"") -> 4.7733333 | O10: =IF(ISNUMBER($K10),IF(ISNUMBER(Parâmetros!$E$4),Parâmetros!$E$4,0),"") -> 0 | P10: =IF(ISNUMBER($K10),$K10-$D10-IF(ISNUMBER($E10),$E10,0)-$L10-$M10-$N10-$O10,"") -> 31.822222 | Q10: =IF(AND(ISNUMBER($K10),$K10>0),$P10/$K10,"") -> 0.2 | S10: =IF(OR(NOT(ISNUMBER($R10)),$R10=0,NOT(ISNUMBER($K10))),"",$K10*(1-$R10)) | T10: =IF(ISNUMBER($S10),$S10*$H10,"") | U10: =IF(ISNUMBER($S10),$S10*Parâmetros!$B$4,"") | V10: =IF(ISNUMBER($S10),$S10*Parâmetros!$C$4,"") | W10: =IF(ISNUMBER($S10),$S10-$D10-IF(ISNUMBER($E10),$E10,0)-$O10-$T10-$U10-$V10,"") | X10: =IF(AND(ISNUMBER($S10),$S10>0),$W10/$S10,"")
A11: =IF(Produtos!$A11="","",Produtos!$A11) -> L2450 | B11: =IF(Produtos!$A11="","",Produtos!$B11) -> Lixeira Aço Inox s/Tampa 24x50 25L | C11: =IF(Produtos!$A11="","",Produtos!$C11) -> Lixeiras em inox | D11: =IF(Produtos!$A11="","",IF(Produtos!$D11="","",Produtos!$D11)) -> 116.34 | F11: =IF($A11="","",IF($C11="","⚠ categoria",IFERROR(INDEX(Parâmetros!$B$13:$B$22,MATCH($C11,Parâmetros!$A$13:$A$22,0)),"⚠ categoria"))) -> 0.13 | H11: =IF($A11="","",IF(ISNUMBER($G11),$G11,IF(ISNUMBER($F11),$F11,""))) -> 0.13 | I11: =IF(OR($A11="",NOT(ISNUMBER($D11)),NOT(ISNUMBER($H11))),"",IF((1-$H11-Parâmetros!$B$4-Parâmetros!$C$4-Parâmetros!$D$4)<=0,"INVALIDO",($D11+IF(ISNUMBER($E11),$E11,0)+IF(ISNUMBER(Parâmetros!$E$4),Parâmetros!$E$4,0))/(1-$H11-Parâmetros!$B$4-Parâmetros!$C$4-Parâmetros!$D$4))) -> 215.44444 | K11: =IF(OR($A11="",NOT(ISNUMBER($D11)),NOT(ISNUMBER($H11))),"",IF(AND(ISNUMBER($J11),$J11>0),$J11,IF(ISNUMBER($I11),$I11,""))) -> 215.44444 | L11: =IF(ISNUMBER($K11),$K11*$H11,"") -> 28.007778 | M11: =IF(ISNUMBER($K11),$K11*Parâmetros!$B$4,"") -> 21.544444 | N11: =IF(ISNUMBER($K11),$K11*Parâmetros!$C$4,"") -> 6.4633333 | O11: =IF(ISNUMBER($K11),IF(ISNUMBER(Parâmetros!$E$4),Parâmetros!$E$4,0),"") -> 0 | P11: =IF(ISNUMBER($K11),$K11-$D11-IF(ISNUMBER($E11),$E11,0)-$L11-$M11-$N11-$O11,"") -> 43.088889 | Q11: =IF(AND(ISNUMBER($K11),$K11>0),$P11/$K11,"") -> 0.2 | S11: =IF(OR(NOT(ISNUMBER($R11)),$R11=0,NOT(ISNUMBER($K11))),"",$K11*(1-$R11)) | T11: =IF(ISNUMBER($S11),$S11*$H11,"") | U11: =IF(ISNUMBER($S11),$S11*Parâmetros!$B$4,"") | V11: =IF(ISNUMBER($S11),$S11*Parâmetros!$C$4,"") | W11: =IF(ISNUMBER($S11),$S11-$D11-IF(ISNUMBER($E11),$E11,0)-$O11-$T11-$U11-$V11,"") | X11: =IF(AND(ISNUMBER($S11),$S11>0),$W11/$S11,"")
A12: =IF(Produtos!$A12="","",Produtos!$A12) -> L2460 | B12: =IF(Produtos!$A12="","",Produtos!$B12) -> Lixeira Aço Inox s/Tampa 24x60 27L | C12: =IF(Produtos!$A12="","",Produtos!$C12) -> Lixeiras em inox | D12: =IF(Produtos!$A12="","",IF(Produtos!$D12="","",Produtos!$D12)) -> 117.84 | F12: =IF($A12="","",IF($C12="","⚠ categoria",IFERROR(INDEX(Parâmetros!$B$13:$B$22,MATCH($C12,Parâmetros!$A$13:$A$22,0)),"⚠ categoria"))) -> 0.13 | H12: =IF($A12="","",IF(ISNUMBER($G12),$G12,IF(ISNUMBER($F12),$F12,""))) -> 0.13 | I12: =IF(OR($A12="",NOT(ISNUMBER($D12)),NOT(ISNUMBER($H12))),"",IF((1-$H12-Parâmetros!$B$4-Parâmetros!$C$4-Parâmetros!$D$4)<=0,"INVALIDO",($D12+IF(ISNUMBER($E12),$E12,0)+IF(ISNUMBER(Parâmetros!$E$4),Parâmetros!$E$4,0))/(1-$H12-Parâmetros!$B$4-Parâmetros!$C$4-Parâmetros!$D$4))) -> 218.22222 | K12: =IF(OR($A12="",NOT(ISNUMBER($D12)),NOT(ISNUMBER($H12))),"",IF(AND(ISNUMBER($J12),$J12>0),$J12,IF(ISNUMBER($I12),$I12,""))) -> 218.22222 | L12: =IF(ISNUMBER($K12),$K12*$H12,"") -> 28.368889 | M12: =IF(ISNUMBER($K12),$K12*Parâmetros!$B$4,"") -> 21.822222 | N12: =IF(ISNUMBER($K12),$K12*Parâmetros!$C$4,"") -> 6.5466667 | O12: =IF(ISNUMBER($K12),IF(ISNUMBER(Parâmetros!$E$4),Parâmetros!$E$4,0),"") -> 0 | P12: =IF(ISNUMBER($K12),$K12-$D12-IF(ISNUMBER($E12),$E12,0)-$L12-$M12-$N12-$O12,"") -> 43.644444 | Q12: =IF(AND(ISNUMBER($K12),$K12>0),$P12/$K12,"") -> 0.2 | S12: =IF(OR(NOT(ISNUMBER($R12)),$R12=0,NOT(ISNUMBER($K12))),"",$K12*(1-$R12)) | T12: =IF(ISNUMBER($S12),$S12*$H12,"") | U12: =IF(ISNUMBER($S12),$S12*Parâmetros!$B$4,"") | V12: =IF(ISNUMBER($S12),$S12*Parâmetros!$C$4,"") | W12: =IF(ISNUMBER($S12),$S12-$D12-IF(ISNUMBER($E12),$E12,0)-$O12-$T12-$U12-$V12,"") | X12: =IF(AND(ISNUMBER($S12),$S12>0),$W12/$S12,"")
A13: =IF(Produtos!$A13="","",Produtos!$A13) -> L2470 | B13: =IF(Produtos!$A13="","",Produtos!$B13) -> Lixeira Aço Inox s/Tampa 24x70 30L | C13: =IF(Produtos!$A13="","",Produtos!$C13) -> Lixeiras em inox | D13: =IF(Produtos!$A13="","",IF(Produtos!$D13="","",Produtos!$D13)) -> 186.46 | F13: =IF($A13="","",IF($C13="","⚠ categoria",IFERROR(INDEX(Parâmetros!$B$13:$B$22,MATCH($C13,Parâmetros!$A$13:$A$22,0)),"⚠ categoria"))) -> 0.13 | H13: =IF($A13="","",IF(ISNUMBER($G13),$G13,IF(ISNUMBER($F13),$F13,""))) -> 0.13 | I13: =IF(OR($A13="",NOT(ISNUMBER($D13)),NOT(ISNUMBER($H13))),"",IF((1-$H13-Parâmetros!$B$4-Parâmetros!$C$4-Parâmetros!$D$4)<=0,"INVALIDO",($D13+IF(ISNUMBER($E13),$E13,0)+IF(ISNUMBER(Parâmetros!$E$4),Parâmetros!$E$4,0))/(1-$H13-Parâmetros!$B$4-Parâmetros!$C$4-Parâmetros!$D$4))) -> 345.2963 | K13: =IF(OR($A13="",NOT(ISNUMBER($D13)),NOT(ISNUMBER($H13))),"",IF(AND(ISNUMBER($J13),$J13>0),$J13,IF(ISNUMBER($I13),$I13,""))) -> 345.2963 | L13: =IF(ISNUMBER($K13),$K13*$H13,"") -> 44.888519 | M13: =IF(ISNUMBER($K13),$K13*Parâmetros!$B$4,"") -> 34.52963 | N13: =IF(ISNUMBER($K13),$K13*Parâmetros!$C$4,"") -> 10.358889 | O13: =IF(ISNUMBER($K13),IF(ISNUMBER(Parâmetros!$E$4),Parâmetros!$E$4,0),"") -> 0 | P13: =IF(ISNUMBER($K13),$K13-$D13-IF(ISNUMBER($E13),$E13,0)-$L13-$M13-$N13-$O13,"") -> 69.059259 | Q13: =IF(AND(ISNUMBER($K13),$K13>0),$P13/$K13,"") -> 0.2 | S13: =IF(OR(NOT(ISNUMBER($R13)),$R13=0,NOT(ISNUMBER($K13))),"",$K13*(1-$R13)) | T13: =IF(ISNUMBER($S13),$S13*$H13,"") | U13: =IF(ISNUMBER($S13),$S13*Parâmetros!$B$4,"") | V13: =IF(ISNUMBER($S13),$S13*Parâmetros!$C$4,"") | W13: =IF(ISNUMBER($S13),$S13-$D13-IF(ISNUMBER($E13),$E13,0)-$O13-$T13-$U13-$V13,"") | X13: =IF(AND(ISNUMBER($S13),$S13>0),$W13/$S13,"")
A14: =IF(Produtos!$A14="","",Produtos!$A14) -> L3040 | B14: =IF(Produtos!$A14="","",Produtos!$B14) -> Lixeira Aço Inox s/Tampa 30x40 30L | C14: =IF(Produtos!$A14="","",Produtos!$C14) -> Lixeiras em inox | D14: =IF(Produtos!$A14="","",IF(Produtos!$D14="","",Produtos!$D14)) -> 116.77 | F14: =IF($A14="","",IF($C14="","⚠ categoria",IFERROR(INDEX(Parâmetros!$B$13:$B$22,MATCH($C14,Parâmetros!$A$13:$A$22,0)),"⚠ categoria"))) -> 0.13 | H14: =IF($A14="","",IF(ISNUMBER($G14),$G14,IF(ISNUMBER($F14),$F14,""))) -> 0.13 | I14: =IF(OR($A14="",NOT(ISNUMBER($D14)),NOT(ISNUMBER($H14))),"",IF((1-$H14-Parâmetros!$B$4-Parâmetros!$C$4-Parâmetros!$D$4)<=0,"INVALIDO",($D14+IF(ISNUMBER($E14),$E14,0)+IF(ISNUMBER(Parâmetros!$E$4),Parâmetros!$E$4,0))/(1-$H14-Parâmetros!$B$4-Parâmetros!$C$4-Parâmetros!$D$4))) -> 216.24074 | K14: =IF(OR($A14="",NOT(ISNUMBER($D14)),NOT(ISNUMBER($H14))),"",IF(AND(ISNUMBER($J14),$J14>0),$J14,IF(ISNUMBER($I14),$I14,""))) -> 216.24074 | L14: =IF(ISNUMBER($K14),$K14*$H14,"") -> 28.111296 | M14: =IF(ISNUMBER($K14),$K14*Parâmetros!$B$4,"") -> 21.624074 | N14: =IF(ISNUMBER($K14),$K14*Parâmetros!$C$4,"") -> 6.4872222 | O14: =IF(ISNUMBER($K14),IF(ISNUMBER(Parâmetros!$E$4),Parâmetros!$E$4,0),"") -> 0 | P14: =IF(ISNUMBER($K14),$K14-$D14-IF(ISNUMBER($E14),$E14,0)-$L14-$M14-$N14-$O14,"") -> 43.248148 | Q14: =IF(AND(ISNUMBER($K14),$K14>0),$P14/$K14,"") -> 0.2 | S14: =IF(OR(NOT(ISNUMBER($R14)),$R14=0,NOT(ISNUMBER($K14))),"",$K14*(1-$R14)) | T14: =IF(ISNUMBER($S14),$S14*$H14,"") | U14: =IF(ISNUMBER($S14),$S14*Parâmetros!$B$4,"") | V14: =IF(ISNUMBER($S14),$S14*Parâmetros!$C$4,"") | W14: =IF(ISNUMBER($S14),$S14-$D14-IF(ISNUMBER($E14),$E14,0)-$O14-$T14-$U14-$V14,"") | X14: =IF(AND(ISNUMBER($S14),$S14>0),$W14/$S14,"")
A15: =IF(Produtos!$A15="","",Produtos!$A15) -> L3050 | B15: =IF(Produtos!$A15="","",Produtos!$B15) -> Lixeira Aço Inox s/Tampa 30x50 35L | C15: =IF(Produtos!$A15="","",Produtos!$C15) -> Lixeiras em inox | D15: =IF(Produtos!$A15="","",IF(Produtos!$D15="","",Produtos!$D15)) -> 159.84 | F15: =IF($A15="","",IF($C15="","⚠ categoria",IFERROR(INDEX(Parâmetros!$B$13:$B$22,MATCH($C15,Parâmetros!$A$13:$A$22,0)),"⚠ categoria"))) -> 0.13 | H15: =IF($A15="","",IF(ISNUMBER($G15),$G15,IF(ISNUMBER($F15),$F15,""))) -> 0.13 | I15: =IF(OR($A15="",NOT(ISNUMBER($D15)),NOT(ISNUMBER($H15))),"",IF((1-$H15-Parâmetros!$B$4-Parâmetros!$C$4-Parâmetros!$D$4)<=0,"INVALIDO",($D15+IF(ISNUMBER($E15),$E15,0)+IF(ISNUMBER(Parâmetros!$E$4),Parâmetros!$E$4,0))/(1-$H15-Parâmetros!$B$4-Parâmetros!$C$4-Parâmetros!$D$4))) -> 296 | K15: =IF(OR($A15="",NOT(ISNUMBER($D15)),NOT(ISNUMBER($H15))),"",IF(AND(ISNUMBER($J15),$J15>0),$J15,IF(ISNUMBER($I15),$I15,""))) -> 296 | L15: =IF(ISNUMBER($K15),$K15*$H15,"") -> 38.48 | M15: =IF(ISNUMBER($K15),$K15*Parâmetros!$B$4,"") -> 29.6 | N15: =IF(ISNUMBER($K15),$K15*Parâmetros!$C$4,"") -> 8.88 | O15: =IF(ISNUMBER($K15),IF(ISNUMBER(Parâmetros!$E$4),Parâmetros!$E$4,0),"") -> 0 | P15: =IF(ISNUMBER($K15),$K15-$D15-IF(ISNUMBER($E15),$E15,0)-$L15-$M15-$N15-$O15,"") -> 59.2 | Q15: =IF(AND(ISNUMBER($K15),$K15>0),$P15/$K15,"") -> 0.2 | S15: =IF(OR(NOT(ISNUMBER($R15)),$R15=0,NOT(ISNUMBER($K15))),"",$K15*(1-$R15)) | T15: =IF(ISNUMBER($S15),$S15*$H15,"") | U15: =IF(ISNUMBER($S15),$S15*Parâmetros!$B$4,"") | V15: =IF(ISNUMBER($S15),$S15*Parâmetros!$C$4,"") | W15: =IF(ISNUMBER($S15),$S15-$D15-IF(ISNUMBER($E15),$E15,0)-$O15-$T15-$U15-$V15,"") | X15: =IF(AND(ISNUMBER($S15),$S15>0),$W15/$S15,"")
A16: =IF(Produtos!$A16="","",Produtos!$A16) -> L3060 | B16: =IF(Produtos!$A16="","",Produtos!$B16) -> Lixeira Aço Inox s/Tampa 30x60 40L | C16: =IF(Produtos!$A16="","",Produtos!$C16) -> Lixeiras em inox | D16: =IF(Produtos!$A16="","",IF(Produtos!$D16="","",Produtos!$D16)) -> 164.99 | F16: =IF($A16="","",IF($C16="","⚠ categoria",IFERROR(INDEX(Parâmetros!$B$13:$B$22,MATCH($C16,Parâmetros!$A$13:$A$22,0)),"⚠ categoria"))) -> 0.13 | H16: =IF($A16="","",IF(ISNUMBER($G16),$G16,IF(ISNUMBER($F16),$F16,""))) -> 0.13 | I16: =IF(OR($A16="",NOT(ISNUMBER($D16)),NOT(ISNUMBER($H16))),"",IF((1-$H16-Parâmetros!$B$4-Parâmetros!$C$4-Parâmetros!$D$4)<=0,"INVALIDO",($D16+IF(ISNUMBER($E16),$E16,0)+IF(ISNUMBER(Parâmetros!$E$4),Parâmetros!$E$4,0))/(1-$H16-Parâmetros!$B$4-Parâmetros!$C$4-Parâmetros!$D$4))) -> 305.53704 | K16: =IF(OR($A16="",NOT(ISNUMBER($D16)),NOT(ISNUMBER($H16))),"",IF(AND(ISNUMBER($J16),$J16>0),$J16,IF(ISNUMBER($I16),$I16,""))) -> 305.53704 | L16: =IF(ISNUMBER($K16),$K16*$H16,"") -> 39.719815 | M16: =IF(ISNUMBER($K16),$K16*Parâmetros!$B$4,"") -> 30.553704 | N16: =IF(ISNUMBER($K16),$K16*Parâmetros!$C$4,"") -> 9.1661111 | O16: =IF(ISNUMBER($K16),IF(ISNUMBER(Parâmetros!$E$4),Parâmetros!$E$4,0),"") -> 0 | P16: =IF(ISNUMBER($K16),$K16-$D16-IF(ISNUMBER($E16),$E16,0)-$L16-$M16-$N16-$O16,"") -> 61.107407 | Q16: =IF(AND(ISNUMBER($K16),$K16>0),$P16/$K16,"") -> 0.2 | S16: =IF(OR(NOT(ISNUMBER($R16)),$R16=0,NOT(ISNUMBER($K16))),"",$K16*(1-$R16)) | T16: =IF(ISNUMBER($S16),$S16*$H16,"") | U16: =IF(ISNUMBER($S16),$S16*Parâmetros!$B$4,"") | V16: =IF(ISNUMBER($S16),$S16*Parâmetros!$C$4,"") | W16: =IF(ISNUMBER($S16),$S16-$D16-IF(ISNUMBER($E16),$E16,0)-$O16-$T16-$U16-$V16,"") | X16: =IF(AND(ISNUMBER($S16),$S16>0),$W16/$S16,"")
A17: =IF(Produtos!$A17="","",Produtos!$A17) -> L3070 | B17: =IF(Produtos!$A17="","",Produtos!$B17) -> Lixeira Aço Inox s/Tampa 30x70 50L | C17: =IF(Produtos!$A17="","",Produtos!$C17) -> Lixeiras em inox | D17: =IF(Produtos!$A17="","",IF(Produtos!$D17="","",Produtos!$D17)) -> 210.17 | F17: =IF($A17="","",IF($C17="","⚠ categoria",IFERROR(INDEX(Parâmetros!$B$13:$B$22,MATCH($C17,Parâmetros!$A$13:$A$22,0)),"⚠ categoria"))) -> 0.13 | H17: =IF($A17="","",IF(ISNUMBER($G17),$G17,IF(ISNUMBER($F17),$F17,""))) -> 0.13 | I17: =IF(OR($A17="",NOT(ISNUMBER($D17)),NOT(ISNUMBER($H17))),"",IF((1-$H17-Parâmetros!$B$4-Parâmetros!$C$4-Parâmetros!$D$4)<=0,"INVALIDO",($D17+IF(ISNUMBER($E17),$E17,0)+IF(ISNUMBER(Parâmetros!$E$4),Parâmetros!$E$4,0))/(1-$H17-Parâmetros!$B$4-Parâmetros!$C$4-Parâmetros!$D$4))) -> 389.2037 | K17: =IF(OR($A17="",NOT(ISNUMBER($D17)),NOT(ISNUMBER($H17))),"",IF(AND(ISNUMBER($J17),$J17>0),$J17,IF(ISNUMBER($I17),$I17,""))) -> 389.2037 | L17: =IF(ISNUMBER($K17),$K17*$H17,"") -> 50.596481 | M17: =IF(ISNUMBER($K17),$K17*Parâmetros!$B$4,"") -> 38.92037 | N17: =IF(ISNUMBER($K17),$K17*Parâmetros!$C$4,"") -> 11.676111 | O17: =IF(ISNUMBER($K17),IF(ISNUMBER(Parâmetros!$E$4),Parâmetros!$E$4,0),"") -> 0 | P17: =IF(ISNUMBER($K17),$K17-$D17-IF(ISNUMBER($E17),$E17,0)-$L17-$M17-$N17-$O17,"") -> 77.840741 | Q17: =IF(AND(ISNUMBER($K17),$K17>0),$P17/$K17,"") -> 0.2 | S17: =IF(OR(NOT(ISNUMBER($R17)),$R17=0,NOT(ISNUMBER($K17))),"",$K17*(1-$R17)) | T17: =IF(ISNUMBER($S17),$S17*$H17,"") | U17: =IF(ISNUMBER($S17),$S17*Parâmetros!$B$4,"") | V17: =IF(ISNUMBER($S17),$S17*Parâmetros!$C$4,"") | W17: =IF(ISNUMBER($S17),$S17-$D17-IF(ISNUMBER($E17),$E17,0)-$O17-$T17-$U17-$V17,"") | X17: =IF(AND(ISNUMBER($S17),$S17>0),$W17/$S17,"")
A18: =IF(Produtos!$A18="","",Produtos!$A18) -> L3085 | B18: =IF(Produtos!$A18="","",Produtos!$B18) -> Lixeira Aço Inox s/Tampa 30x85 60L | C18: =IF(Produtos!$A18="","",Produtos!$C18) -> Lixeiras em inox | D18: =IF(Produtos!$A18="","",IF(Produtos!$D18="","",Produtos!$D18)) -> 266.36 | F18: =IF($A18="","",IF($C18="","⚠ categoria",IFERROR(INDEX(Parâmetros!$B$13:$B$22,MATCH($C18,Parâmetros!$A$13:$A$22,0)),"⚠ categoria"))) -> 0.13 | H18: =IF($A18="","",IF(ISNUMBER($G18),$G18,IF(ISNUMBER($F18),$F18,""))) -> 0.13 | I18: =IF(OR($A18="",NOT(ISNUMBER($D18)),NOT(ISNUMBER($H18))),"",IF((1-$H18-Parâmetros!$B$4-Parâmetros!$C$4-Parâmetros!$D$4)<=0,"INVALIDO",($D18+IF(ISNUMBER($E18),$E18,0)+IF(ISNUMBER(Parâmetros!$E$4),Parâmetros!$E$4,0))/(1-$H18-Parâmetros!$B$4-Parâmetros!$C$4-Parâmetros!$D$4))) -> 493.25926 | K18: =IF(OR($A18="",NOT(ISNUMBER($D18)),NOT(ISNUMBER($H18))),"",IF(AND(ISNUMBER($J18),$J18>0),$J18,IF(ISNUMBER($I18),$I18,""))) -> 493.25926 | L18: =IF(ISNUMBER($K18),$K18*$H18,"") -> 64.123704 | M18: =IF(ISNUMBER($K18),$K18*Parâmetros!$B$4,"") -> 49.325926 | N18: =IF(ISNUMBER($K18),$K18*Parâmetros!$C$4,"") -> 14.797778 | O18: =IF(ISNUMBER($K18),IF(ISNUMBER(Parâmetros!$E$4),Parâmetros!$E$4,0),"") -> 0 | P18: =IF(ISNUMBER($K18),$K18-$D18-IF(ISNUMBER($E18),$E18,0)-$L18-$M18-$N18-$O18,"") -> 98.651852 | Q18: =IF(AND(ISNUMBER($K18),$K18>0),$P18/$K18,"") -> 0.2 | S18: =IF(OR(NOT(ISNUMBER($R18)),$R18=0,NOT(ISNUMBER($K18))),"",$K18*(1-$R18)) | T18: =IF(ISNUMBER($S18),$S18*$H18,"") | U18: =IF(ISNUMBER($S18),$S18*Parâmetros!$B$4,"") | V18: =IF(ISNUMBER($S18),$S18*Parâmetros!$C$4,"") | W18: =IF(ISNUMBER($S18),$S18-$D18-IF(ISNUMBER($E18),$E18,0)-$O18-$T18-$U18-$V18,"") | X18: =IF(AND(ISNUMBER($S18),$S18>0),$W18/$S18,"")
A19: =IF(Produtos!$A19="","",Produtos!$A19) -> L4050 | B19: =IF(Produtos!$A19="","",Produtos!$B19) -> Lixeira Aço Inox s/Tampa 40x50 62L | C19: =IF(Produtos!$A19="","",Produtos!$C19) -> Lixeiras em inox | D19: =IF(Produtos!$A19="","",IF(Produtos!$D19="","",Produtos!$D19)) -> 221.01 | F19: =IF($A19="","",IF($C19="","⚠ categoria",IFERROR(INDEX(Parâmetros!$B$13:$B$22,MATCH($C19,Parâmetros!$A$13:$A$22,0)),"⚠ categoria"))) -> 0.13 | H19: =IF($A19="","",IF(ISNUMBER($G19),$G19,IF(ISNUMBER($F19),$F19,""))) -> 0.13 | I19: =IF(OR($A19="",NOT(ISNUMBER($D19)),NOT(ISNUMBER($H19))),"",IF((1-$H19-Parâmetros!$B$4-Parâmetros!$C$4-Parâmetros!$D$4)<=0,"INVALIDO",($D19+IF(ISNUMBER($E19),$E19,0)+IF(ISNUMBER(Parâmetros!$E$4),Parâmetros!$E$4,0))/(1-$H19-Parâmetros!$B$4-Parâmetros!$C$4-Parâmetros!$D$4))) -> 409.27778 | K19: =IF(OR($A19="",NOT(ISNUMBER($D19)),NOT(ISNUMBER($H19))),"",IF(AND(ISNUMBER($J19),$J19>0),$J19,IF(ISNUMBER($I19),$I19,""))) -> 409.27778 | L19: =IF(ISNUMBER($K19),$K19*$H19,"") -> 53.206111 | M19: =IF(ISNUMBER($K19),$K19*Parâmetros!$B$4,"") -> 40.927778 | N19: =IF(ISNUMBER($K19),$K19*Parâmetros!$C$4,"") -> 12.278333 | O19: =IF(ISNUMBER($K19),IF(ISNUMBER(Parâmetros!$E$4),Parâmetros!$E$4,0),"") -> 0 | P19: =IF(ISNUMBER($K19),$K19-$D19-IF(ISNUMBER($E19),$E19,0)-$L19-$M19-$N19-$O19,"") -> 81.855556 | Q19: =IF(AND(ISNUMBER($K19),$K19>0),$P19/$K19,"") -> 0.2 | S19: =IF(OR(NOT(ISNUMBER($R19)),$R19=0,NOT(ISNUMBER($K19))),"",$K19*(1-$R19)) | T19: =IF(ISNUMBER($S19),$S19*$H19,"") | U19: =IF(ISNUMBER($S19),$S19*Parâmetros!$B$4,"") | V19: =IF(ISNUMBER($S19),$S19*Parâmetros!$C$4,"") | W19: =IF(ISNUMBER($S19),$S19-$D19-IF(ISNUMBER($E19),$E19,0)-$O19-$T19-$U19-$V19,"") | X19: =IF(AND(ISNUMBER($S19),$S19>0),$W19/$S19,"")
... A24: =IF(Produtos!$A24="","",Produtos!$A24) -> L4090 | B24: =IF(Produtos!$A24="","",Produtos!$B24) -> Lixeira Aço Inox s/Tampa 40x90 120L | C24: =IF(Produtos!$A24="","",Produtos!$C24) -> Lixeiras em inox | D24: =IF(Produtos!$A24="","",IF(Produtos!$D24="","",Produtos!$D24)) -> 378.85 | F24: =IF($A24="","",IF($C24="","⚠ categoria",IFERROR(INDEX(Parâmetros!$B$13:$B$22,MATCH($C24,Parâmetros!$A$13:$A$22,0)),"⚠ categoria"))) -> 0.13 | H24: =IF($A24="","",IF(ISNUMBER($G24),$G24,IF(ISNUMBER($F24),$F24,""))) -> 0.13 | I24: =IF(OR($A24="",NOT(ISNUMBER($D24)),NOT(ISNUMBER($H24))),"",IF((1-$H24-Parâmetros!$B$4-Parâmetros!$C$4-Parâmetros!$D$4)<=0,"INVALIDO",($D24+IF(ISNUMBER($E24),$E24,0)+IF(ISNUMBER(Parâmetros!$E$4),Parâmetros!$E$4,0))/(1-$H24-Parâmetros!$B$4-Parâmetros!$C$4-Parâmetros!$D$4))) -> 701.57407 | K24: =IF(OR($A24="",NOT(ISNUMBER($D24)),NOT(ISNUMBER($H24))),"",IF(AND(ISNUMBER($J24),$J24>0),$J24,IF(ISNUMBER($I24),$I24,""))) -> 701.57407 | L24: =IF(ISNUMBER($K24),$K24*$H24,"") -> 91.20463 | M24: =IF(ISNUMBER($K24),$K24*Parâmetros!$B$4,"") -> 70.157407 | N24: =IF(ISNUMBER($K24),$K24*Parâmetros!$C$4,"") -> 21.047222 | O24: =IF(ISNUMBER($K24),IF(ISNUMBER(Parâmetros!$E$4),Parâmetros!$E$4,0),"") -> 0 | P24: =IF(ISNUMBER($K24),$K24-$D24-IF(ISNUMBER($E24),$E24,0)-$L24-$M24-$N24-$O24,"") -> 140.31481 | Q24: =IF(AND(ISNUMBER($K24),$K24>0),$P24/$K24,"") -> 0.2 | S24: =IF(OR(NOT(ISNUMBER($R24)),$R24=0,NOT(ISNUMBER($K24))),"",$K24*(1-$R24)) | T24: =IF(ISNUMBER($S24),$S24*$H24,"") | U24: =IF(ISNUMBER($S24),$S24*Parâmetros!$B$4,"") | V24: =IF(ISNUMBER($S24),$S24*Parâmetros!$C$4,"") | W24: =IF(ISNUMBER($S24),$S24-$D24-IF(ISNUMBER($E24),$E24,0)-$O24-$T24-$U24-$V24,"") | X24: =IF(AND(ISNUMBER($S24),$S24>0),$W24/$S24,"")
A25: =IF(Produtos!$A25="","",Produtos!$A25) -> L1618-A | B25: =IF(Produtos!$A25="","",Produtos!$B25) -> Lixeira Aço Inox c/Aro 16x18 03L | C25: =IF(Produtos!$A25="","",Produtos!$C25) -> Lixeiras em inox | D25: =IF(Produtos!$A25="","",IF(Produtos!$D25="","",Produtos!$D25)) -> 48.18 | E25: 14.15 | F25: =IF($A25="","",IF($C25="","⚠ categoria",IFERROR(INDEX(Parâmetros!$B$13:$B$22,MATCH($C25,Parâmetros!$A$13:$A$22,0)),"⚠ categoria"))) -> 0.13 | H25: =IF($A25="","",IF(ISNUMBER($G25),$G25,IF(ISNUMBER($F25),$F25,""))) -> 0.13 | I25: =IF(OR($A25="",NOT(ISNUMBER($D25)),NOT(ISNUMBER($H25))),"",IF((1-$H25-Parâmetros!$B$4-Parâmetros!$C$4-Parâmetros!$D$4)<=0,"INVALIDO",($D25+IF(ISNUMBER($E25),$E25,0)+IF(ISNUMBER(Parâmetros!$E$4),Parâmetros!$E$4,0))/(1-$H25-Parâmetros!$B$4-Parâmetros!$C$4-Parâmetros!$D$4))) -> 115.42593 | J25: 90.35 | K25: =IF(OR($A25="",NOT(ISNUMBER($D25)),NOT(ISNUMBER($H25))),"",IF(AND(ISNUMBER($J25),$J25>0),$J25,IF(ISNUMBER($I25),$I25,""))) -> 90.35 | L25: =IF(ISNUMBER($K25),$K25*$H25,"") -> 11.7455 | M25: =IF(ISNUMBER($K25),$K25*Parâmetros!$B$4,"") -> 9.035 | N25: =IF(ISNUMBER($K25),$K25*Parâmetros!$C$4,"") -> 2.7105 | O25: =IF(ISNUMBER($K25),IF(ISNUMBER(Parâmetros!$E$4),Parâmetros!$E$4,0),"") -> 0 | P25: =IF(ISNUMBER($K25),$K25-$D25-IF(ISNUMBER($E25),$E25,0)-$L25-$M25-$N25-$O25,"") -> 4.529 | Q25: =IF(AND(ISNUMBER($K25),$K25>0),$P25/$K25,"") -> 0.050127283 | S25: =IF(OR(NOT(ISNUMBER($R25)),$R25=0,NOT(ISNUMBER($K25))),"",$K25*(1-$R25)) | T25: =IF(ISNUMBER($S25),$S25*$H25,"") | U25: =IF(ISNUMBER($S25),$S25*Parâmetros!$B$4,"") | V25: =IF(ISNUMBER($S25),$S25*Parâmetros!$C$4,"") | W25: =IF(ISNUMBER($S25),$S25-$D25-IF(ISNUMBER($E25),$E25,0)-$O25-$T25-$U25-$V25,"") | X25: =IF(AND(ISNUMBER($S25),$S25>0),$W25/$S25,"")
A26: =IF(Produtos!$A26="","",Produtos!$A26) -> L1623-A | B26: =IF(Produtos!$A26="","",Produtos!$B26) -> Lixeira Aço Inox c/Aro 16x23 05L | C26: =IF(Produtos!$A26="","",Produtos!$C26) -> Lixeiras em inox | D26: =IF(Produtos!$A26="","",IF(Produtos!$D26="","",Produtos!$D26)) -> 55.75 | E26: 16.45 | F26: =IF($A26="","",IF($C26="","⚠ categoria",IFERROR(INDEX(Parâmetros!$B$13:$B$22,MATCH($C26,Parâmetros!$A$13:$A$22,0)),"⚠ categoria"))) -> 0.13 | H26: =IF($A26="","",IF(ISNUMBER($G26),$G26,IF(ISNUMBER($F26),$F26,""))) -> 0.13 | I26: =IF(OR($A26="",NOT(ISNUMBER($D26)),NOT(ISNUMBER($H26))),"",IF((1-$H26-Parâmetros!$B$4-Parâmetros!$C$4-Parâmetros!$D$4)<=0,"INVALIDO",($D26+IF(ISNUMBER($E26),$E26,0)+IF(ISNUMBER(Parâmetros!$E$4),Parâmetros!$E$4,0))/(1-$H26-Parâmetros!$B$4-Parâmetros!$C$4-Parâmetros!$D$4))) -> 133.7037 | J26: 104.62 | K26: =IF(OR($A26="",NOT(ISNUMBER($D26)),NOT(ISNUMBER($H26))),"",IF(AND(ISNUMBER($J26),$J26>0),$J26,IF(ISNUMBER($I26),$I26,""))) -> 104.62 | L26: =IF(ISNUMBER($K26),$K26*$H26,"") -> 13.6006 | M26: =IF(ISNUMBER($K26),$K26*Parâmetros!$B$4,"") -> 10.462 | N26: =IF(ISNUMBER($K26),$K26*Parâmetros!$C$4,"") -> 3.1386 | O26: =IF(ISNUMBER($K26),IF(ISNUMBER(Parâmetros!$E$4),Parâmetros!$E$4,0),"") -> 0 | P26: =IF(ISNUMBER($K26),$K26-$D26-IF(ISNUMBER($E26),$E26,0)-$L26-$M26-$N26-$O26,"") -> 5.2188 | Q26: =IF(AND(ISNUMBER($K26),$K26>0),$P26/$K26,"") -> 0.049883387 | S26: =IF(OR(NOT(ISNUMBER($R26)),$R26=0,NOT(ISNUMBER($K26))),"",$K26*(1-$R26)) | T26: =IF(ISNUMBER($S26),$S26*$H26,"") | U26: =IF(ISNUMBER($S26),$S26*Parâmetros!$B$4,"") | V26: =IF(ISNUMBER($S26),$S26*Parâmetros!$C$4,"") | W26: =IF(ISNUMBER($S26),$S26-$D26-IF(ISNUMBER($E26),$E26,0)-$O26-$T26-$U26-$V26,"") | X26: =IF(AND(ISNUMBER($S26),$S26>0),$W26/$S26,"")
A27: =IF(Produtos!$A27="","",Produtos!$A27) -> L2025-A | B27: =IF(Produtos!$A27="","",Produtos!$B27) -> Lixeira Aço Inox c/Aro 20x25 07L | C27: =IF(Produtos!$A27="","",Produtos!$C27) -> Lixeiras em inox | D27: =IF(Produtos!$A27="","",IF(Produtos!$D27="","",Produtos!$D27)) -> 60.21 | E27: 16.85 | F27: =IF($A27="","",IF($C27="","⚠ categoria",IFERROR(INDEX(Parâmetros!$B$13:$B$22,MATCH($C27,Parâmetros!$A$13:$A$22,0)),"⚠ categoria"))) -> 0.13 | H27: =IF($A27="","",IF(ISNUMBER($G27),$G27,IF(ISNUMBER($F27),$F27,""))) -> 0.13 | I27: =IF(OR($A27="",NOT(ISNUMBER($D27)),NOT(ISNUMBER($H27))),"",IF((1-$H27-Parâmetros!$B$4-Parâmetros!$C$4-Parâmetros!$D$4)<=0,"INVALIDO",($D27+IF(ISNUMBER($E27),$E27,0)+IF(ISNUMBER(Parâmetros!$E$4),Parâmetros!$E$4,0))/(1-$H27-Parâmetros!$B$4-Parâmetros!$C$4-Parâmetros!$D$4))) -> 142.7037 | J27: 111.81 | K27: =IF(OR($A27="",NOT(ISNUMBER($D27)),NOT(ISNUMBER($H27))),"",IF(AND(ISNUMBER($J27),$J27>0),$J27,IF(ISNUMBER($I27),$I27,""))) -> 111.81 | L27: =IF(ISNUMBER($K27),$K27*$H27,"") -> 14.5353 | M27: =IF(ISNUMBER($K27),$K27*Parâmetros!$B$4,"") -> 11.181 | N27: =IF(ISNUMBER($K27),$K27*Parâmetros!$C$4,"") -> 3.3543 | O27: =IF(ISNUMBER($K27),IF(ISNUMBER(Parâmetros!$E$4),Parâmetros!$E$4,0),"") -> 0 | P27: =IF(ISNUMBER($K27),$K27-$D27-IF(ISNUMBER($E27),$E27,0)-$L27-$M27-$N27-$O27,"") -> 5.6794 | Q27: =IF(AND(ISNUMBER($K27),$K27>0),$P27/$K27,"") -> 0.050795099 | S27: =IF(OR(NOT(ISNUMBER($R27)),$R27=0,NOT(ISNUMBER($K27))),"",$K27*(1-$R27)) | T27: =IF(ISNUMBER($S27),$S27*$H27,"") | U27: =IF(ISNUMBER($S27),$S27*Parâmetros!$B$4,"") | V27: =IF(ISNUMBER($S27),$S27*Parâmetros!$C$4,"") | W27: =IF(ISNUMBER($S27),$S27-$D27-IF(ISNUMBER($E27),$E27,0)-$O27-$T27-$U27-$V27,"") | X27: =IF(AND(ISNUMBER($S27),$S27>0),$W27/$S27,"")
A28: =IF(Produtos!$A28="","",Produtos!$A28) -> L2030-A | B28: =IF(Produtos!$A28="","",Produtos!$B28) -> Lixeira Aço Inox c/Aro 20x30 10L | C28: =IF(Produtos!$A28="","",Produtos!$C28) -> Lixeiras em inox | D28: =IF(Produtos!$A28="","",IF(Produtos!$D28="","",Produtos!$D28)) -> 68.57 | E28: 24.35 | F28: =IF($A28="","",IF($C28="","⚠ categoria",IFERROR(INDEX(Parâmetros!$B$13:$B$22,MATCH($C28,Parâmetros!$A$13:$A$22,0)),"⚠ categoria"))) -> 0.13 | G28: 0.12 | H28: =IF($A28="","",IF(ISNUMBER($G28),$G28,IF(ISNUMBER($F28),$F28,""))) -> 0.12 | I28: =IF(OR($A28="",NOT(ISNUMBER($D28)),NOT(ISNUMBER($H28))),"",IF((1-$H28-Parâmetros!$B$4-Parâmetros!$C$4-Parâmetros!$D$4)<=0,"INVALIDO",($D28+IF(ISNUMBER($E28),$E28,0)+IF(ISNUMBER(Parâmetros!$E$4),Parâmetros!$E$4,0))/(1-$H28-Parâmetros!$B$4-Parâmetros!$C$4-Parâmetros!$D$4))) -> 168.94545 | J28: 169.467 | K28: =IF(OR($A28="",NOT(ISNUMBER($D28)),NOT(ISNUMBER($H28))),"",IF(AND(ISNUMBER($J28),$J28>0),$J28,IF(ISNUMBER($I28),$I28,""))) -> 169.467 | L28: =IF(ISNUMBER($K28),$K28*$H28,"") -> 20.33604 | M28: =IF(ISNUMBER($K28),$K28*Parâmetros!$B$4,"") -> 16.9467 | N28: =IF(ISNUMBER($K28),$K28*Parâmetros!$C$4,"") -> 5.08401 | O28: =IF(ISNUMBER($K28),IF(ISNUMBER(Parâmetros!$E$4),Parâmetros!$E$4,0),"") -> 0 | P28: =IF(ISNUMBER($K28),$K28-$D28-IF(ISNUMBER($E28),$E28,0)-$L28-$M28-$N28-$O28,"") -> 34.18025 | Q28: =IF(AND(ISNUMBER($K28),$K28>0),$P28/$K28,"") -> 0.20169266 | S28: =IF(OR(NOT(ISNUMBER($R28)),$R28=0,NOT(ISNUMBER($K28))),"",$K28*(1-$R28)) | T28: =IF(ISNUMBER($S28),$S28*$H28,"") | U28: =IF(ISNUMBER($S28),$S28*Parâmetros!$B$4,"") | V28: =IF(ISNUMBER($S28),$S28*Parâmetros!$C$4,"") | W28: =IF(ISNUMBER($S28),$S28-$D28-IF(ISNUMBER($E28),$E28,0)-$O28-$T28-$U28-$V28,"") | X28: =IF(AND(ISNUMBER($S28),$S28>0),$W28/$S28,"") | Y28: 02/10
A29: =IF(Produtos!$A29="","",Produtos!$A29) -> L2425-A | B29: =IF(Produtos!$A29="","",Produtos!$B29) -> Lixeira Aço Inox c/Aro 24x25 13L | C29: =IF(Produtos!$A29="","",Produtos!$C29) -> Lixeiras em inox | D29: =IF(Produtos!$A29="","",IF(Produtos!$D29="","",Produtos!$D29)) -> 79.66 | E29: 24.35 | F29: =IF($A29="","",IF($C29="","⚠ categoria",IFERROR(INDEX(Parâmetros!$B$13:$B$22,MATCH($C29,Parâmetros!$A$13:$A$22,0)),"⚠ categoria"))) -> 0.13 | G29: 0.12 | H29: =IF($A29="","",IF(ISNUMBER($G29),$G29,IF(ISNUMBER($F29),$F29,""))) -> 0.12 | I29: =IF(OR($A29="",NOT(ISNUMBER($D29)),NOT(ISNUMBER($H29))),"",IF((1-$H29-Parâmetros!$B$4-Parâmetros!$C$4-Parâmetros!$D$4)<=0,"INVALIDO",($D29+IF(ISNUMBER($E29),$E29,0)+IF(ISNUMBER(Parâmetros!$E$4),Parâmetros!$E$4,0))/(1-$H29-Parâmetros!$B$4-Parâmetros!$C$4-Parâmetros!$D$4))) -> 189.10909 | J29: 189.85618 | K29: =IF(OR($A29="",NOT(ISNUMBER($D29)),NOT(ISNUMBER($H29))),"",IF(AND(ISNUMBER($J29),$J29>0),$J29,IF(ISNUMBER($I29),$I29,""))) -> 189.85618 | L29: =IF(ISNUMBER($K29),$K29*$H29,"") -> 22.782741 | M29: =IF(ISNUMBER($K29),$K29*Parâmetros!$B$4,"") -> 18.985618 | N29: =IF(ISNUMBER($K29),$K29*Parâmetros!$C$4,"") -> 5.6956853 | O29: =IF(ISNUMBER($K29),IF(ISNUMBER(Parâmetros!$E$4),Parâmetros!$E$4,0),"") -> 0 | P29: =IF(ISNUMBER($K29),$K29-$D29-IF(ISNUMBER($E29),$E29,0)-$L29-$M29-$N29-$O29,"") -> 38.382131 | Q29: =IF(AND(ISNUMBER($K29),$K29>0),$P29/$K29,"") -> 0.20216425 | S29: =IF(OR(NOT(ISNUMBER($R29)),$R29=0,NOT(ISNUMBER($K29))),"",$K29*(1-$R29)) | T29: =IF(ISNUMBER($S29),$S29*$H29,"") | U29: =IF(ISNUMBER($S29),$S29*Parâmetros!$B$4,"") | V29: =IF(ISNUMBER($S29),$S29*Parâmetros!$C$4,"") | W29: =IF(ISNUMBER($S29),$S29-$D29-IF(ISNUMBER($E29),$E29,0)-$O29-$T29-$U29-$V29,"") | X29: =IF(AND(ISNUMBER($S29),$S29>0),$W29/$S29,"") | Y29: 02/10
A30: =IF(Produtos!$A30="","",Produtos!$A30) -> L2430-A | B30: =IF(Produtos!$A30="","",Produtos!$B30) -> Lixeira Aço Inox c/Aro 24x30 15L | C30: =IF(Produtos!$A30="","",Produtos!$C30) -> Lixeiras em inox | D30: =IF(Produtos!$A30="","",IF(Produtos!$D30="","",Produtos!$D30)) -> 91.16 | E30: 27.05 | F30: =IF($A30="","",IF($C30="","⚠ categoria",IFERROR(INDEX(Parâmetros!$B$13:$B$22,MATCH($C30,Parâmetros!$A$13:$A$22,0)),"⚠ categoria"))) -> 0.13 | G30: 0.12 | H30: =IF($A30="","",IF(ISNUMBER($G30),$G30,IF(ISNUMBER($F30),$F30,""))) -> 0.12 | I30: =IF(OR($A30="",NOT(ISNUMBER($D30)),NOT(ISNUMBER($H30))),"",IF((1-$H30-Parâmetros!$B$4-Parâmetros!$C$4-Parâmetros!$D$4)<=0,"INVALIDO",($D30+IF(ISNUMBER($E30),$E30,0)+IF(ISNUMBER(Parâmetros!$E$4),Parâmetros!$E$4,0))/(1-$H30-Parâmetros!$B$4-Parâmetros!$C$4-Parâmetros!$D$4))) -> 214.92727 | J30: 216.407 | K30: =IF(OR($A30="",NOT(ISNUMBER($D30)),NOT(ISNUMBER($H30))),"",IF(AND(ISNUMBER($J30),$J30>0),$J30,IF(ISNUMBER($I30),$I30,""))) -> 216.407 | L30: =IF(ISNUMBER($K30),$K30*$H30,"") -> 25.96884 | M30: =IF(ISNUMBER($K30),$K30*Parâmetros!$B$4,"") -> 21.6407 | N30: =IF(ISNUMBER($K30),$K30*Parâmetros!$C$4,"") -> 6.49221 | O30: =IF(ISNUMBER($K30),IF(ISNUMBER(Parâmetros!$E$4),Parâmetros!$E$4,0),"") -> 0 | P30: =IF(ISNUMBER($K30),$K30-$D30-IF(ISNUMBER($E30),$E30,0)-$L30-$M30-$N30-$O30,"") -> 44.09525 | Q30: =IF(AND(ISNUMBER($K30),$K30>0),$P30/$K30,"") -> 0.20376074 | S30: =IF(OR(NOT(ISNUMBER($R30)),$R30=0,NOT(ISNUMBER($K30))),"",$K30*(1-$R30)) | T30: =IF(ISNUMBER($S30),$S30*$H30,"") | U30: =IF(ISNUMBER($S30),$S30*Parâmetros!$B$4,"") | V30: =IF(ISNUMBER($S30),$S30*Parâmetros!$C$4,"") | W30: =IF(ISNUMBER($S30),$S30-$D30-IF(ISNUMBER($E30),$E30,0)-$O30-$T30-$U30-$V30,"") | X30: =IF(AND(ISNUMBER($S30),$S30>0),$W30/$S30,"") | Y30: 09/10
A31: =IF(Produtos!$A31="","",Produtos!$A31) -> L2440-A | B31: =IF(Produtos!$A31="","",Produtos!$B31) -> Lixeira Aço Inox c/Aro 24x40 20L | C31: =IF(Produtos!$A31="","",Produtos!$C31) -> Lixeiras em inox | D31: =IF(Produtos!$A31="","",IF(Produtos!$D31="","",Produtos!$D31)) -> 102.19 | E31: 29.25 | F31: =IF($A31="","",IF($C31="","⚠ categoria",IFERROR(INDEX(Parâmetros!$B$13:$B$22,MATCH($C31,Parâmetros!$A$13:$A$22,0)),"⚠ categoria"))) -> 0.13 | G31: 0.12 | H31: =IF($A31="","",IF(ISNUMBER($G31),$G31,IF(ISNUMBER($F31),$F31,""))) -> 0.12 | I31: =IF(OR($A31="",NOT(ISNUMBER($D31)),NOT(ISNUMBER($H31))),"",IF((1-$H31-Parâmetros!$B$4-Parâmetros!$C$4-Parâmetros!$D$4)<=0,"INVALIDO",($D31+IF(ISNUMBER($E31),$E31,0)+IF(ISNUMBER(Parâmetros!$E$4),Parâmetros!$E$4,0))/(1-$H31-Parâmetros!$B$4-Parâmetros!$C$4-Parâmetros!$D$4))) -> 238.98182 | J31: 240.24192 | K31: =IF(OR($A31="",NOT(ISNUMBER($D31)),NOT(ISNUMBER($H31))),"",IF(AND(ISNUMBER($J31),$J31>0),$J31,IF(ISNUMBER($I31),$I31,""))) -> 240.24192 | L31: =IF(ISNUMBER($K31),$K31*$H31,"") -> 28.82903 | M31: =IF(ISNUMBER($K31),$K31*Parâmetros!$B$4,"") -> 24.024192 | N31: =IF(ISNUMBER($K31),$K31*Parâmetros!$C$4,"") -> 7.2072575 | O31: =IF(ISNUMBER($K31),IF(ISNUMBER(Parâmetros!$E$4),Parâmetros!$E$4,0),"") -> 0 | P31: =IF(ISNUMBER($K31),$K31-$D31-IF(ISNUMBER($E31),$E31,0)-$L31-$M31-$N31-$O31,"") -> 48.741437 | Q31: =IF(AND(ISNUMBER($K31),$K31>0),$P31/$K31,"") -> 0.20288482 | S31: =IF(OR(NOT(ISNUMBER($R31)),$R31=0,NOT(ISNUMBER($K31))),"",$K31*(1-$R31)) | T31: =IF(ISNUMBER($S31),$S31*$H31,"") | U31: =IF(ISNUMBER($S31),$S31*Parâmetros!$B$4,"") | V31: =IF(ISNUMBER($S31),$S31*Parâmetros!$C$4,"") | W31: =IF(ISNUMBER($S31),$S31-$D31-IF(ISNUMBER($E31),$E31,0)-$O31-$T31-$U31-$V31,"") | X31: =IF(AND(ISNUMBER($S31),$S31>0),$W31/$S31,"") | Y31: 02/10
A32: =IF(Produtos!$A32="","",Produtos!$A32) -> L2450-A | B32: =IF(Produtos!$A32="","",Produtos!$B32) -> Lixeira Aço Inox c/Aro 24x50 25L | C32: =IF(Produtos!$A32="","",Produtos!$C32) -> Lixeiras em inox | D32: =IF(Produtos!$A32="","",IF(Produtos!$D32="","",Produtos!$D32)) -> 132.03 | E32: 45.25 | F32: =IF($A32="","",IF($C32="","⚠ categoria",IFERROR(INDEX(Parâmetros!$B$13:$B$22,MATCH($C32,Parâmetros!$A$13:$A$22,0)),"⚠ categoria"))) -> 0.13 | G32: 0.12 | H32: =IF($A32="","",IF(ISNUMBER($G32),$G32,IF(ISNUMBER($F32),$F32,""))) -> 0.12 | I32: =IF(OR($A32="",NOT(ISNUMBER($D32)),NOT(ISNUMBER($H32))),"",IF((1-$H32-Parâmetros!$B$4-Parâmetros!$C$4-Parâmetros!$D$4)<=0,"INVALIDO",($D32+IF(ISNUMBER($E32),$E32,0)+IF(ISNUMBER(Parâmetros!$E$4),Parâmetros!$E$4,0))/(1-$H32-Parâmetros!$B$4-Parâmetros!$C$4-Parâmetros!$D$4))) -> 322.32727 | J32: 325.6 | K32: =IF(OR($A32="",NOT(ISNUMBER($D32)),NOT(ISNUMBER($H32))),"",IF(AND(ISNUMBER($J32),$J32>0),$J32,IF(ISNUMBER($I32),$I32,""))) -> 325.6 | L32: =IF(ISNUMBER($K32),$K32*$H32,"") -> 39.072 | M32: =IF(ISNUMBER($K32),$K32*Parâmetros!$B$4,"") -> 32.56 | N32: =IF(ISNUMBER($K32),$K32*Parâmetros!$C$4,"") -> 9.768 | O32: =IF(ISNUMBER($K32),IF(ISNUMBER(Parâmetros!$E$4),Parâmetros!$E$4,0),"") -> 0 | P32: =IF(ISNUMBER($K32),$K32-$D32-IF(ISNUMBER($E32),$E32,0)-$L32-$M32-$N32-$O32,"") -> 66.92 | Q32: =IF(AND(ISNUMBER($K32),$K32>0),$P32/$K32,"") -> 0.20552826 | S32: =IF(OR(NOT(ISNUMBER($R32)),$R32=0,NOT(ISNUMBER($K32))),"",$K32*(1-$R32)) | T32: =IF(ISNUMBER($S32),$S32*$H32,"") | U32: =IF(ISNUMBER($S32),$S32*Parâmetros!$B$4,"") | V32: =IF(ISNUMBER($S32),$S32*Parâmetros!$C$4,"") | W32: =IF(ISNUMBER($S32),$S32-$D32-IF(ISNUMBER($E32),$E32,0)-$O32-$T32-$U32-$V32,"") | X32: =IF(AND(ISNUMBER($S32),$S32>0),$W32/$S32,"") | Y32: 09/10
A33: =IF(Produtos!$A33="","",Produtos!$A33) -> L2460-A | B33: =IF(Produtos!$A33="","",Produtos!$B33) -> Lixeira Aço Inox c/Aro 24x60 27L | C33: =IF(Produtos!$A33="","",Produtos!$C33) -> Lixeiras em inox | D33: =IF(Produtos!$A33="","",IF(Produtos!$D33="","",Produtos!$D33)) -> 136.09 | E33: 40.85 | F33: =IF($A33="","",IF($C33="","⚠ categoria",IFERROR(INDEX(Parâmetros!$B$13:$B$22,MATCH($C33,Parâmetros!$A$13:$A$22,0)),"⚠ categoria"))) -> 0.13 | G33: 0.12 | H33: =IF($A33="","",IF(ISNUMBER($G33),$G33,IF(ISNUMBER($F33),$F33,""))) -> 0.12 | I33: =IF(OR($A33="",NOT(ISNUMBER($D33)),NOT(ISNUMBER($H33))),"",IF((1-$H33-Parâmetros!$B$4-Parâmetros!$C$4-Parâmetros!$D$4)<=0,"INVALIDO",($D33+IF(ISNUMBER($E33),$E33,0)+IF(ISNUMBER(Parâmetros!$E$4),Parâmetros!$E$4,0))/(1-$H33-Parâmetros!$B$4-Parâmetros!$C$4-Parâmetros!$D$4))) -> 321.70909 | J33: 321.882 | K33: =IF(OR($A33="",NOT(ISNUMBER($D33)),NOT(ISNUMBER($H33))),"",IF(AND(ISNUMBER($J33),$J33>0),$J33,IF(ISNUMBER($I33),$I33,""))) -> 321.882 | L33: =IF(ISNUMBER($K33),$K33*$H33,"") -> 38.62584 | M33: =IF(ISNUMBER($K33),$K33*Parâmetros!$B$4,"") -> 32.1882 | N33: =IF(ISNUMBER($K33),$K33*Parâmetros!$C$4,"") -> 9.65646 | O33: =IF(ISNUMBER($K33),IF(ISNUMBER(Parâmetros!$E$4),Parâmetros!$E$4,0),"") -> 0 | P33: =IF(ISNUMBER($K33),$K33-$D33-IF(ISNUMBER($E33),$E33,0)-$L33-$M33-$N33-$O33,"") -> 64.4715 | Q33: =IF(AND(ISNUMBER($K33),$K33>0),$P33/$K33,"") -> 0.20029545 | S33: =IF(OR(NOT(ISNUMBER($R33)),$R33=0,NOT(ISNUMBER($K33))),"",$K33*(1-$R33)) | T33: =IF(ISNUMBER($S33),$S33*$H33,"") | U33: =IF(ISNUMBER($S33),$S33*Parâmetros!$B$4,"") | V33: =IF(ISNUMBER($S33),$S33*Parâmetros!$C$4,"") | W33: =IF(ISNUMBER($S33),$S33-$D33-IF(ISNUMBER($E33),$E33,0)-$O33-$T33-$U33-$V33,"") | X33: =IF(AND(ISNUMBER($S33),$S33>0),$W33/$S33,"") | Y33: 02/10
